Workbook

Sheet 00_Dashboard
A1: HSCS 2569 PCH Interactive Workbook
A2: Patient Safety Culture Survey | สร้างจาก HSCS PCH2026 (Responses).xlsx | คะแนนเป็นร้อยละคำตอบเชิงบวก
A4: Executive Metrics | B4: Value | D4: Dimension | E4: % Positive | F4: Status
A5: Raw rows | B5: =COUNTA(Source_Raw!$A$2:$A$59) -> 58 | D5: 1. การทำงานเป็นทีม | E5: =AVERAGE(HSCS2569!$C$4:$C$6) -> 57.471264 | F5: =IF(E5<60,"ควรพัฒนาด่วน",IF(E5<=70,"เร่งพัฒนา",IF(E5<=80,"ควรพัฒนาต่อเนื่อง","ควรส่งเสริม"))) -> ควรพัฒนาด่วน
A6: Rows used for analysis | B6: =COUNTIF(Raw_Data!$A$2:$A$59,"Yes") -> 58 | D6: 2. บุคลากรและพื้นที่การทำงาน | E6: =AVERAGE(HSCS2569!$C$7:$C$10) -> 36.206897 | F6: =IF(E6<60,"ควรพัฒนาด่วน",IF(E6<=70,"เร่งพัฒนา",IF(E6<=80,"ควรพัฒนาต่อเนื่อง","ควรส่งเสริม"))) -> ควรพัฒนาด่วน
A7: Excluded rows | B7: =B5-B6 -> 0 | D7: 3. การเป็นองค์กรแห่งการเรียนรู้ มีการพัฒนาอย่างต่อเนื่อง | E7: =AVERAGE(HSCS2569!$C$11:$C$13) -> 59.770115 | F7: =IF(E7<60,"ควรพัฒนาด่วน",IF(E7<=70,"เร่งพัฒนา",IF(E7<=80,"ควรพัฒนาต่อเนื่อง","ควรส่งเสริม"))) -> ควรพัฒนาด่วน
A8: Respondents | B8: =COUNTA(Raw_Data!$B$2:$B$59) -> 58 | D8: 4. การตอบสนองต่อความคลาดเคลื่อน | E8: =AVERAGE(HSCS2569!$C$14:$C$17) -> 44.396552 | F8: =IF(E8<60,"ควรพัฒนาด่วน",IF(E8<=70,"เร่งพัฒนา",IF(E8<=80,"ควรพัฒนาต่อเนื่อง","ควรส่งเสริม"))) -> ควรพัฒนาด่วน
A9: Items | B9: =COUNTA(Item_Metadata!$A$2:$A$33) -> 32 | D9: 5. การสนับสนุนของหัวหน้างาน, ผู้จัดการ หรือทีมนำทางคลินิกในเรื่องความปลอดภัย | E9: =AVERAGE(HSCS2569!$C$18:$C$20) -> 52.298851 | F9: =IF(E9<60,"ควรพัฒนาด่วน",IF(E9<=70,"เร่งพัฒนา",IF(E9<=80,"ควรพัฒนาต่อเนื่อง","ควรส่งเสริม"))) -> ควรพัฒนาด่วน
A10: Dimensions | B10: =COUNTA(_xlfn.UNIQUE(Item_Metadata!$B$2:$B$33)) -> 10 | D10: 6. การสื่อสารเรื่องความคลาดเคลื่อน | E10: =AVERAGE(HSCS2569!$C$21:$C$23) -> 62.068966 | F10: =IF(E10<60,"ควรพัฒนาด่วน",IF(E10<=70,"เร่งพัฒนา",IF(E10<=80,"ควรพัฒนาต่อเนื่อง","ควรส่งเสริม"))) -> เร่งพัฒนา
A11: กลุ่มตามสายงาน | B11: =COUNTA(_xlfn.UNIQUE(Raw_Data!$E$2:$E$59)) -> 4 | D11: 7. การสื่อสารที่เปิดกว้าง | E11: =AVERAGE(HSCS2569!$C$24:$C$27) -> 52.155172 | F11: =IF(E11<60,"ควรพัฒนาด่วน",IF(E11<=70,"เร่งพัฒนา",IF(E11<=80,"ควรพัฒนาต่อเนื่อง","ควรส่งเสริม"))) -> ควรพัฒนาด่วน
A12: พื้นที่ปฏิบัติงาน | B12: =COUNTA(_xlfn.UNIQUE(Raw_Data!$D$2:$D$59)) -> 18 | D12: 8. การรายงานเหตุการณ์ความปลอดภัยของผู้ป่วย/ผู้รับบริการ | E12: =AVERAGE(HSCS2569!$C$28:$C$29) -> 43.103448 | F12: =IF(E12<60,"ควรพัฒนาด่วน",IF(E12<=70,"เร่งพัฒนา",IF(E12<=80,"ควรพัฒนาต่อเนื่อง","ควรส่งเสริม"))) -> ควรพัฒนาด่วน
A13: Overall Positive Score | B13: =AVERAGE(HSCS2569!$C$4:$C$35) -> 53.232759 | D13: 9. การสนับสนุนจากทีมผู้บริหารของสถานพยาบาลในเรื่องความปลอดภัยของผู้ป่วย /ผู้รับบริการ | E13: =AVERAGE(HSCS2569!$C$30:$C$32) -> 64.367816 | F13: =IF(E13<60,"ควรพัฒนาด่วน",IF(E13<=70,"เร่งพัฒนา",IF(E13<=80,"ควรพัฒนาต่อเนื่อง","ควรส่งเสริม"))) -> เร่งพัฒนา
A14: ข้อที่ควรพัฒนาด่วน (<60) | B14: =COUNTIF(HSCS2569!$C$4:$C$35,"<60") -> 19 | D14: 10. การส่งต่องานและแลกเปลี่ยนข้อมูล ในการเปลี่ยนผ่านระหว่างหน่วยงานหรือเวร | E14: =AVERAGE(HSCS2569!$C$33:$C$35) -> 66.091954 | F14: =IF(E14<60,"ควรพัฒนาด่วน",IF(E14<=70,"เร่งพัฒนา",IF(E14<=80,"ควรพัฒนาต่อเนื่อง","ควรส่งเสริม"))) -> เร่งพัฒนา
A15: ข้อเร่งพัฒนา (60–70) | B15: =COUNTIFS(HSCS2569!$C$4:$C$35,">=60",HSCS2569!$C$4:$C$35,"<=70") -> 10
A17: เกณฑ์สี: แดง <60 | ส้ม 60–70 | เหลือง 70.1–80 | เขียว >80
A18: การคิดคะแนน: ข้อเชิงบวก = 4–5; ข้อเชิงลบ = 1–2; ตัวหารใช้เฉพาะคำตอบที่มีค่า 1–5

Sheet Source_Raw
A1: Timestamp | B1: กลุ่มตามสายงาน | C1: พื้นที่ปฏิบัติงาน | D1: A1. ในหน่วยงานหรือพื้นที่ที่ท่านทำงานอยู่ ทุกคนทำงานร่วมกันเป็นทีมอย่างมีประสิทธิภาพ | E1: A2. ในหน่วยงานหรือพื้นที่นี้มีจำนวนบุคลากรในการทำงานที่เพียงพอที่จะรับมือกับปริมาณงานหรือภาระงานของหน่วยงานที่กำหนด | F1: A3. ในหน่วยงานที่ท่านทำงานมีบุคลากรที่ทำงานจำนวนชั่วโมงต่อเนื่องยาวนานมากกว่าที่เหมาะสมต่อการดูแลผู้ป่วยหรือผู้รับบริการได้ดี | G1: A4. หน่วยงานที่ท่านทำงานอยู่มีการทบทวนกระบวนการทำงานอย่างสม่ำเสมอเพื่อพิจารณาว่าจำเป็นต้องมีการเปลี่ยนแปลงใดบ้างที่ควรปรับปรุงแก้ไขเพื่อความปลอดภัยของผู้ป่วยหรือผู้รับบริการ | H1: A5. หน่วยงานที่ท่านทำงานอยู่ต้องอาศัยหรือพึ่งพาบุคลากรที่มาช่วยทำงานชั่วคราว บุคลากรที่หมุนเวียนมาทำงาน หรือที่ทำงานเฉพาะช่วงที่กำหนดเป็นครั้งๆ มากเกินไป | I1: A6. ในหน่วยงานที่ท่านทำงานอยู่ บุคลากรรู้สึกว่าความผิดพลาดคลาดเคลื่อนที่อาจเกิดขึ้นในการทำงานจะถูกนำมากล่าวโทษกับตัวบุคคล | J1: A7. เมื่อมีการรายงานเหตุการณ์หรืออุบัติการณ์ในหน่วยงานที่ท่านทำงานอยู่ มักมีการระบุว่าเป็นความผิดหรือตำหนิตัวบุคคลเสมอ | K1: A8. ในช่วงเวลาที่มีภาระงานยุ่งมาก หรือยาก บุคลากรในหน่วยงานที่ท่านทำงานอยู่จะช่วยเหลือซึ่งกันและกันอย่างดี | L1: A9. ในหน่วยงานที่ท่านทำงานอยู่มีปัญหาเรื่องพฤติกรรมในการทำงานของบุคลากรที่ไม่เคารพซึ่งกันและกัน | M1: A10. เมื่อบุคลากรทำงานผิดพลาดหรือคลาดเคลื่อน หน่วยงานที่ท่านทำงานอยู่จะมุ่งเน้นที่การเรียนรู้มากกว่าการกล่าวโทษตัวบุคคล | N1: A11. หน่วยงานที่ท่านทำงานอยู่มักจะเร่งรีบในการทำงานมากเกินไปจนส่งผลกระทบในเชิงลบต่อความปลอดภัยของผู้ป่วยหรือผู้รับบริการ | O1: A12. หน่วยงานที่ท่านทำงานอยู่มีการเปลี่ยนแปลงเพื่อเพิ่มความปลอดภัยให้กับผู้ป่วย/ผู้รับบริการ และมีการประเมินผลความปลอดภัยของผู้ป่วย/ผู้รับบริการว่าดีขึ้นอย่างไร | P1: A13. ในหน่วยงานที่ท่านทำงานอยู่ปล่อยให้เกิดปัญหาเรื่องความปลอดภัยกับผู้ป่วย/ผู้รับบริการในเรื่องเดิมและเกิดขึ้นซ้ำๆ | Q1: A14. ในหน่วยงานที่ท่านทำงานอยู่ไม่มีการสนับสนุนหรือการดูแลบุคลากรที่เกี่ยวข้องกับอุบัติการณ์ความคลาดเคลื่อน หรือเหตุการณ์ไม่พึงประสงค์เกี่ยวกับความปลอดภัยของผู้ป่วย/ผู้รับบริการ | R1: B1. หัวหน้างาน หัวหน้ากลุ่มงาน ผู้จัดการ หัวหน้าทีมการดูแลผู้ป่วย หรือประธานทีมนำทางคลินิกของฉันให้ความสำคัญกับข้อเสนอแนะของบุคลากรและผู้ร่วมงานอย่างจริงจังเพื่อปรับปรุงความปลอดภัยของผู้ป่วย | S1: B2. หัวหน้างาน หัวหน้ากลุ่มงาน ผู้จัดการ หัวหน้าทีมการดูแลผู้ป่วย หรือประธานทีมนำทางคลินิกของฉันต้องการให้เราทำงานเร็วขึ้นในช่วงเวลาที่ภาระงานยุ่งยาก ชุลมุนหรือเร่งรีบ แม้ว่าต้องลัดขั้นตอนหรือกระบวนการ | T1: B3. หัวหน้างาน หัวหน้ากลุ่มงาน ผู้จัดการ หัวหน้าทีมการดูแลผู้ป่วย หรือประธานทีมนำทางคลินิกของฉันมีการดำเนินการเพื่อตอบและแก้ไขความกังวลเรื่องความปลอดภัยของผู้ป่วย/ผู้รับบริการที่ได้รับทราบด้วยความตั้งใจ | U1: C1. บุคลากรได้รับการสื่อสารให้ข้อมูลกรณีเกิดความคลาดเคลื่อนขึ้นในหน่วยงานหรือพื้นที่ปฏิบัติงานของตน | V1: C2. เมื่อเกิดข้อผิดพลาดหรือความคลาดเคลื่อนในหน่วยงานที่ทำงานอยู่ บุคลากรจะพูดถึงวิธีป้องกันความคลาดเคลื่อนไม่ให้เกิดขึ้นซ้ำอีก | W1: C3. ในหน่วยงานที่ฉันปฏิบัติงานอยู่ บุคลากรได้รับการให้ข้อมูลหรือสื่อสารการเปลี่ยนแปลงที่เกิดขึ้นจากรายงานอุบัติการณ์ | X1: C4. ในหน่วยงานที่ฉันปฏิบัติงานอยู่ บุคลากรสามารถพูดหรือบอกกล่าวได้ทันที เมื่อพบเห็นบางสิ่งบางอย่างที่อาจจะมีผลกระทบหรือผลเสียต่อการดูแลผู้ป่วยหรือผู้รับบริการ | Y1: C5. ในหน่วยงานที่ฉันปฏิบัติงานอยู่ เมื่อบุคลากรเห็นผู้ที่มีอำนาจ ตำแหน่ง หรือบทบาทหน้าที่สูงกว่า ทำสิ่งที่ไม่ปลอดภัยสำหรับผู้ป่วย/ผู้รับบริการ บุคลากรสามารถพูดหรือบอกกล่าวได้ทันที | Z1: C6. เมื่อบุคลากรของหน่วยงานที่ฉันปฏิบัติงานอยู่ มีข้อกังวลเรื่องความปลอดภัยของผู้ป่วย/ผู้รับบริการ สามารถพูดหรือบอกกล่าวทันที โดยผู้ที่มีอำนาจ ตำแหน่ง หรือบทบาทหน้าที่สูงกว่าเปิดกว้างในการรับฟัง | AA1: C7. ในหน่วยงานที่ฉันปฏิบัติงานอยู่ บุคลากรกลัวที่จะตั้งคำถามเมื่อพบสิ่งที่ไม่ถูกต้องหรือผิดปกติ | AB1: D1. เมื่อเกิดความผิดพลาดหรือคลาดเคลื่อนขึ้นแต่มีการดักจับหรือแก้ไขได้ก่อนถึงตัวผู้ป่วย มีการรายงานอุบัติการณ์ดังกล่าวบ่อยเพียงใด | AC1: D2. เมื่อเกิดความผิดพลาดหรือคลาดเคลื่อนถึงตัวผู้ป่วย/ผู้รับบริการและอาจทำให้ได้รับอันตรายแต่ไม่เกิดอันตราย มีการรายงานอุบัติการณ์ดังกล่าวบ่อยเพียงใด | AD1: F1. การกระทำหรือการดำเนินการของผู้บริหารสถานพยาบาลแสดงให้เห็นถึงการให้ความสำคัญสูงสุดในเรื่องความปลอดภัยของผู้ป่วย/ผู้รับบริการ | AE1: F2. ผู้บริหารสถานพยาบาลจัดสรรทรัพยากรอย่างเพียงพอเพื่อปรับปรุงและเพิ่มความปลอดภัยของผู้ป่วยและผู้รับบริการในระบบบริการ | AF1: F3. ผู้บริหารโรงพยาบาลเหมือนจะให้ความสนใจเรื่องความปลอดภัยของผู้ป่วย/ผู้รับบริการ เฉพาะกรณีเกิดเหตุการณ์ไม่พึงประสงค์ขึ้นแล้วเท่านั้น | AG1: F4. เมื่อย้ายผู้ป่วย/ผู้รับบริการจากหน่วยงานหรือพื้นที่หนึ่งไปยังอีกหน่วยงานหรืออีกพื้นที่หนึ่ง ข้อมูลสำคัญของผู้ป่วยและการรักษา มักถูกละทิ้งโดยไม่มีการส่งต่อ | AH1: F5. ระหว่างการเปลี่ยนเวรหรือกะการทำงาน ข้อมูลสำคัญในการดูแลผู้ป่วย/ผู้รับบริการ มักถูกละทิ้งหรือละเลยโดยไม่มีการส่งต่อ | AI1: F6. ระหว่างการเปลี่ยนเวรหรือกะการทำงานมีเวลาเพียงพอในการแลกเปลี่ยนและส่งต่อข้อมูลสำคัญการดูแลผู้ป่วย/ผู้รับบริการ ที่สำคัญทั้งหมด | AJ1: H1
A2: 46245.491 | B2: สายวิชาชีพสาธารณสุข | C2: ฝ่ายการพยาบาล | D2: 1 | E2: 1 | F2: 2 | G2: 1 | H2: 5 | I2: 5 | J2: 5 | K2: 2 | L2: 5 | M2: 3 | N2: 5 | O2: 4 | P2: 5 | Q2: 3 | R2: 1 | S2: 1 | T2: 3 | U2: 5 | V2: 4 | W2: 5 | X2: 2 | Y2: 1 | Z2: 5 | AA2: 4 | AB2: 2 | AC2: 4 | AD2: 4 | AE2: 5 | AF2: 5 | AG2: 1 | AH2: 1 | AI2: 1
A3: 46245.495 | B3: สายสนับสนุนทางการแพทย์ | C3: ห้องเอ็กซเรย์ | D3: 4 | E3: 4 | F3: 2 | G3: 3 | H3: 4 | I3: 2 | J3: 2 | K3: 4 | L3: 1 | M3: 4 | N3: 1 | O3: 4 | P3: 1 | Q3: 3 | R3: 3 | S3: 2 | T3: 4 | U3: 4 | V3: 3 | W3: 4 | X3: 4 | Y3: 3 | Z3: 4 | AA3: 3 | AB3: 4 | AC3: 3 | AD3: 5 | AE3: 5 | AF3: 1 | AG3: 1 | AH3: 1 | AI3: 5
A4: 46245.497 | B4: สายสนับสนุนทางการแพทย์ | C4: ห้องแลป | D4: 4 | E4: 5 | F4: 1 | G4: 4 | H4: 1 | I4: 1 | J4: 1 | K4: 3 | L4: 3 | M4: 4 | N4: 3 | O4: 3 | P4: 1 | Q4: 1 | R4: 3 | S4: 2 | T4: 2 | U4: 2 | V4: 3 | W4: 3 | X4: 3 | Y4: 4 | Z4: 4 | AA4: 4 | AB4: 5 | AC4: 5 | AD4: 3 | AE4: 3 | AF4: 3 | AG4: 3 | AH4: 3 | AI4: 3
A5: 46245.502 | B5: สายวิชาชีพสาธารณสุข | C5: ERและเปล | D5: 4 | E5: 3 | F5: 3 | G5: 3 | H5: 3 | I5: 3 | J5: 3 | K5: 3 | L5: 3 | M5: 3 | N5: 3 | O5: 4 | P5: 1 | Q5: 1 | R5: 3 | S5: 2 | T5: 3 | U5: 4 | V5: 4 | W5: 3 | X5: 4 | Y5: 2 | Z5: 3 | AA5: 3 | AB5: 3 | AC5: 4 | AD5: 5 | AE5: 4 | AF5: 3 | AG5: 1 | AH5: 1 | AI5: 5 | AJ5: ในบางครั้งเมื่อเจอเหตุการณ์ไม่มีเวลาลงจนลืมและบางคนเห็นว่าลงแล้วไม่มีอะไรเปลี่ยนแปลงไม่เห็นมีใครactionอะไร
A6: 46245.517 | B6: สายสนับสนุนทางการแพทย์ | C6: ห้องเอ็กซเรย์ | D6: 4 | E6: 4 | F6: 2 | G6: 4 | H6: 4 | I6: 2 | J6: 2 | K6: 4 | L6: 1 | M6: 4 | N6: 1 | O6: 4 | P6: 2 | Q6: 1 | R6: 4 | S6: 2 | T6: 4 | U6: 4 | V6: 4 | W6: 3 | X6: 4 | Y6: 3 | Z6: 4 | AA6: 3 | AB6: 4 | AC6: 3 | AD6: 4 | AE6: 4 | AF6: 4 | AG6: 4 | AH6: 3 | AI6: 3 | AJ6: มีระบบเรื่องความปลอดภัยในการระมัดระวังไม่ให้ผู้ป่วยบาดเจ็บเพิ่มเติมได้ดี และเมื่อพบเห็นเหตุการณ์ที่มีความเสี่ยงทุกแผนกมีความกล้าที่จะรายงานอุบัติการณ์มาก็ขึ้น
A7: 46245.527 | B7: สายสนับสนุนทั่วไป | C7: ยานพาหนะ | D7: 3 | E7: 3 | F7: 3 | G7: 4 | H7: 2 | I7: 4 | J7: 4 | K7: 3 | L7: 4 | M7: 5 | N7: 1 | O7: 5 | P7: 1 | Q7: 1 | R7: 5 | S7: 3 | T7: 5 | U7: 5 | V7: 5 | W7: 5 | X7: 5 | Y7: 5 | Z7: 5 | AA7: 1 | AB7: 5 | AC7: 5 | AD7: 5 | AE7: 5 | AF7: 2 | AG7: 1 | AH7: 1 | AI7: 5 | AJ7: ควรมีการวิเคราะห์ประเด็นปัญหาอย่างชีดเจนและเป็นขั้นตอน
A8: 46245.53 | B8: สายสนับสนุนทางการแพทย์ | C8: ห้องยา | D8: 5 | E8: 5 | F8: 3 | G8: 5 | H8: 3 | I8: 2 | J8: 1 | K8: 5 | L8: 1 | M8: 1 | N8: 1 | O8: 1 | P8: 1 | Q8: 1 | R8: 5 | S8: 4 | T8: 5 | U8: 5 | V8: 5 | W8: 5 | X8: 5 | Y8: 5 | Z8: 5 | AA8: 1 | AB8: 5 | AC8: 5 | AD8: 5 | AE8: 5 | AF8: 1 | AG8: 1 | AH8: 1 | AI8: 5 | AJ8: -
A9: 46245.545 | B9: สายวิชาชีพสาธารณสุข | C9: ERและเปล | D9: 4 | E9: 3 | F9: 3 | G9: 3 | H9: 3 | I9: 2 | J9: 2 | K9: 4 | L9: 2 | M9: 3 | N9: 3 | O9: 4 | P9: 1 | Q9: 1 | R9: 4 | S9: 3 | T9: 3 | U9: 4 | V9: 5 | W9: 5 | X9: 4 | Y9: 4 | Z9: 4 | AA9: 2 | AB9: 3 | AC9: 5 | AD9: 5 | AE9: 3 | AF9: 1 | AG9: 2 | AH9: 1 | AI9: 5 | AJ9: มีการติดตามความเสี่ยงสำคัญแต่ความเสี่ยงบางอย่างแก้ไม่ได้โดยระบบเช่นเรื่องคนไข้รอหมอนานช่วงต่อเวร เราไม่สารถแก้ไขในส่วนที่เป็นองค์กรแพทย์ได้โดยตรงแต่บางเรื่องสามารถเล่าให้ผอ.ฟังได้ในภาพรวม
A10: 46245.545 | B10: สายสนับสนุนทั่วไป | C10: การเงิน | D10: 3 | E10: 3 | F10: 3 | G10: 4 | H10: 2 | I10: 3 | J10: 4 | K10: 3 | L10: 4 | M10: 4 | N10: 3 | O10: 4 | P10: 3 | Q10: 3 | R10: 4 | S10: 4 | T10: 4 | U10: 3 | V10: 4 | W10: 4 | X10: 4 | Y10: 4 | Z10: 4 | AA10: 3 | AB10: 3 | AC10: 4 | AD10: 4 | AE10: 4 | AF10: 4 | AG10: 3 | AH10: 3 | AI10: 3 | AJ10: เพิ่มความปลอดภัยให้กับบุคลากรของรพ.
A11: 46245.547 | B11: สายสนับสนุนทางการแพทย์ | C11: IT | D11: 4 | E11: 3 | F11: 4 | G11: 4 | H11: 3 | I11: 4 | J11: 4 | K11: 5 | L11: 4 | M11: 3 | N11: 3 | O11: 4 | P11: 2 | Q11: 2 | R11: 4 | S11: 3 | T11: 4 | U11: 4 | V11: 5 | W11: 4 | X11: 5 | Y11: 5 | Z11: 5 | AA11: 1 | AB11: 4 | AC11: 4 | AD11: 5 | AE11: 4 | AF11: 2 | AG11: 2 | AH11: 3 | AI11: 2 | AJ11: .
A12: 46245.552 | B12: สายสนับสนุนทั่วไป | C12: IT | D12: 4 | E12: 3 | F12: 3 | G12: 4 | H12: 2 | I12: 3 | J12: 2 | K12: 5 | L12: 1 | M12: 4 | N12: 2 | O12: 3 | P12: 2 | Q12: 3 | R12: 5 | S12: 1 | T12: 5 | U12: 2 | V12: 5 | W12: 5 | X12: 5 | Y12: 5 | Z12: 5 | AA12: 2 | AB12: 5 | AC12: 3 | AD12: 5 | AE12: 5 | AF12: 1 | AG12: 1 | AH12: 1 | AI12: 5 | AJ12: -
A13: 46245.556 | B13: สายวิชาชีพสาธารณสุข | C13: OR | D13: 4 | E13: 3 | F13: 1 | G13: 4 | H13: 2 | I13: 3 | J13: 1 | K13: 4 | L13: 2 | M13: 2 | N13: 1 | O13: 5 | P13: 5 | Q13: 1 | R13: 3 | S13: 4 | T13: 3 | U13: 4 | V13: 5 | W13: 3 | X13: 4 | Y13: 2 | Z13: 2 | AA13: 3 | AB13: 4 | AC13: 4 | AD13: 5 | AE13: 4 | AF13: 4 | AG13: 4 | AH13: 4 | AI13: 4 | AJ13: ดี
A14: 46245.56 | B14: สายสนับสนุนทั่วไป | C14: HR | D14: 4 | E14: 4 | F14: 2 | G14: 4 | H14: 3 | I14: 3 | J14: 3 | K14: 4 | L14: 4 | M14: 3 | N14: 3 | O14: 4 | P14: 2 | Q14: 3 | R14: 4 | S14: 2 | T14: 4 | U14: 4 | V14: 4 | W14: 3 | X14: 4 | Y14: 4 | Z14: 3 | AA14: 3 | AB14: 3 | AC14: 4 | AD14: 4 | AE14: 4 | AF14: 2 | AG14: 1 | AH14: 2 | AI14: 4 | AJ14: มีความปลอดภัยตามมาตรฐานโรงพยาบาล
A15: 46245.577 | B15: สายสนับสนุนทั่วไป | C15: ช่างและสนาม | D15: 5 | E15: 4 | F15: 2 | G15: 5 | H15: 3 | I15: 1 | J15: 1 | K15: 5 | L15: 1 | M15: 4 | N15: 1 | O15: 3 | P15: 1 | Q15: 1 | R15: 4 | S15: 1 | T15: 4 | U15: 4 | V15: 5 | W15: 3 | X15: 5 | Y15: 4 | Z15: 3 | AA15: 3 | AB15: 3 | AC15: 3 | AD15: 4 | AE15: 4 | AF15: 2 | AG15: 2 | AH15: 1 | AI15: 4 | AJ15: ช่วยกันสอดส่องดูแลและ สังเกตุสิ่งผิดปกติในโรงพยาบาล ที่จะก่อให้เกิดอันตรายต่อพนักงานและผู้รับบริการ
A16: 46245.578 | B16: สายสนับสนุนทั่วไป | C16: เคหรักษ์ | D16: 3 | E16: 2 | F16: 3 | G16: 3 | H16: 3 | I16: 3 | J16: 3 | K16: 3 | L16: 3 | M16: 3 | N16: 3 | O16: 2 | P16: 3 | Q16: 3 | R16: 3 | S16: 3 | T16: 3 | U16: 3 | V16: 3 | W16: 3 | X16: 3 | Y16: 3 | Z16: 3 | AA16: 3 | AB16: 3 | AC16: 3 | AD16: 3 | AE16: 3 | AF16: 3 | AG16: 3 | AH16: 3 | AI16: 3 | AJ16: ช่วยกันดูแลความปบอดภัย
... A59: 46249.502 | B59: ผู้บริหาร | C59: IPD | D59: 5 | E59: 4 | F59: 4 | G59: 4 | H59: 4 | I59: 3 | J59: 3 | K59: 4 | L59: 2 | M59: 4 | N59: 3 | O59: 4 | P59: 3 | Q59: 2 | R59: 4 | S59: 2 | T59: 4 | U59: 4 | V59: 4 | W59: 4 | X59: 4 | Y59: 4 | Z59: 4 | AA59: 3 | AB59: 4 | AC59: 5 | AD59: 5 | AE59: 5 | AF59: 5 | AG59: 1 | AH59: 2 | AI59: 4 | AJ59: -

Sheet Raw_Data
A1: Include_In_Analysis | B1: Response_ID | C1: Timestamp | D1: พื้นที่ปฏิบัติงาน | E1: กลุ่มตามสายงาน | F1: กลุ่มงาน | G1: A1 | H1: A8 | I1: A9 | J1: A2 | K1: A3 | L1: A5 | M1: A11 | N1: A4 | O1: A12 | P1: A14 | Q1: A6 | R1: A7 | S1: A10 | T1: A13 | U1: B1 | V1: B2 | W1: B3 | X1: C1 | Y1: C2 | Z1: C3 | AA1: C4 | AB1: C5 | AC1: C6 | AD1: C7 | AE1: D1 | AF1: D2 | AG1: F1 | AH1: F2 | AI1: F3 | AJ1: F4 | AK1: F5 | AL1: F6 | AM1: H1 | AN1: H2
A2: Yes | B2: 1 | C2: 46245.491 | D2: ฝ่ายการพยาบาล | E2: สายวิชาชีพสาธารณสุข | F2: สายวิชาชีพสาธารณสุข | G2: 1 | H2: 2 | I2: 5 | J2: 1 | K2: 2 | L2: 5 | M2: 5 | N2: 1 | O2: 4 | P2: 3 | Q2: 5 | R2: 5 | S2: 3 | T2: 5 | U2: 1 | V2: 1 | W2: 3 | X2: 5 | Y2: 4 | Z2: 5 | AA2: 2 | AB2: 1 | AC2: 5 | AD2: 4 | AE2: 2 | AF2: 4 | AG2: 4 | AH2: 5 | AI2: 5 | AJ2: 1 | AK2: 1 | AL2: 1
A3: Yes | B3: 2 | C3: 46245.495 | D3: ห้องเอ็กซเรย์ | E3: สายสนับสนุนทางการแพทย์ | F3: สายสนับสนุนทางการแพทย์ | G3: 4 | H3: 4 | I3: 1 | J3: 4 | K3: 2 | L3: 4 | M3: 1 | N3: 3 | O3: 4 | P3: 3 | Q3: 2 | R3: 2 | S3: 4 | T3: 1 | U3: 3 | V3: 2 | W3: 4 | X3: 4 | Y3: 3 | Z3: 4 | AA3: 4 | AB3: 3 | AC3: 4 | AD3: 3 | AE3: 4 | AF3: 3 | AG3: 5 | AH3: 5 | AI3: 1 | AJ3: 1 | AK3: 1 | AL3: 5
A4: Yes | B4: 3 | C4: 46245.497 | D4: ห้องแลป | E4: สายสนับสนุนทางการแพทย์ | F4: สายสนับสนุนทางการแพทย์ | G4: 4 | H4: 3 | I4: 3 | J4: 5 | K4: 1 | L4: 1 | M4: 3 | N4: 4 | O4: 3 | P4: 1 | Q4: 1 | R4: 1 | S4: 4 | T4: 1 | U4: 3 | V4: 2 | W4: 2 | X4: 2 | Y4: 3 | Z4: 3 | AA4: 3 | AB4: 4 | AC4: 4 | AD4: 4 | AE4: 5 | AF4: 5 | AG4: 3 | AH4: 3 | AI4: 3 | AJ4: 3 | AK4: 3 | AL4: 3
A5: Yes | B5: 4 | C5: 46245.502 | D5: ERและเปล | E5: สายวิชาชีพสาธารณสุข | F5: สายวิชาชีพสาธารณสุข | G5: 4 | H5: 3 | I5: 3 | J5: 3 | K5: 3 | L5: 3 | M5: 3 | N5: 3 | O5: 4 | P5: 1 | Q5: 3 | R5: 3 | S5: 3 | T5: 1 | U5: 3 | V5: 2 | W5: 3 | X5: 4 | Y5: 4 | Z5: 3 | AA5: 4 | AB5: 2 | AC5: 3 | AD5: 3 | AE5: 3 | AF5: 4 | AG5: 5 | AH5: 4 | AI5: 3 | AJ5: 1 | AK5: 1 | AL5: 5 | AM5: ในบางครั้งเมื่อเจอเหตุการณ์ไม่มีเวลาลงจนลืมและบางคนเห็นว่าลงแล้วไม่มีอะไรเปลี่ยนแปลงไม่เห็นมีใครactionอะไร
A6: Yes | B6: 5 | C6: 46245.517 | D6: ห้องเอ็กซเรย์ | E6: สายสนับสนุนทางการแพทย์ | F6: สายสนับสนุนทางการแพทย์ | G6: 4 | H6: 4 | I6: 1 | J6: 4 | K6: 2 | L6: 4 | M6: 1 | N6: 4 | O6: 4 | P6: 1 | Q6: 2 | R6: 2 | S6: 4 | T6: 2 | U6: 4 | V6: 2 | W6: 4 | X6: 4 | Y6: 4 | Z6: 3 | AA6: 4 | AB6: 3 | AC6: 4 | AD6: 3 | AE6: 4 | AF6: 3 | AG6: 4 | AH6: 4 | AI6: 4 | AJ6: 4 | AK6: 3 | AL6: 3 | AM6: มีระบบเรื่องความปลอดภัยในการระมัดระวังไม่ให้ผู้ป่วยบาดเจ็บเพิ่มเติมได้ดี และเมื่อพบเห็นเหตุการณ์ที่มีความเสี่ยงทุกแผนกมีความกล้าที่จะรายงานอุบัติการณ์มาก็ขึ้น
A7: Yes | B7: 6 | C7: 46245.527 | D7: ยานพาหนะ | E7: สายสนับสนุนทั่วไป | F7: สายสนับสนุนทั่วไป | G7: 3 | H7: 3 | I7: 4 | J7: 3 | K7: 3 | L7: 2 | M7: 1 | N7: 4 | O7: 5 | P7: 1 | Q7: 4 | R7: 4 | S7: 5 | T7: 1 | U7: 5 | V7: 3 | W7: 5 | X7: 5 | Y7: 5 | Z7: 5 | AA7: 5 | AB7: 5 | AC7: 5 | AD7: 1 | AE7: 5 | AF7: 5 | AG7: 5 | AH7: 5 | AI7: 2 | AJ7: 1 | AK7: 1 | AL7: 5 | AM7: ควรมีการวิเคราะห์ประเด็นปัญหาอย่างชีดเจนและเป็นขั้นตอน
A8: Yes | B8: 7 | C8: 46245.53 | D8: ห้องยา | E8: สายสนับสนุนทางการแพทย์ | F8: สายสนับสนุนทางการแพทย์ | G8: 5 | H8: 5 | I8: 1 | J8: 5 | K8: 3 | L8: 3 | M8: 1 | N8: 5 | O8: 1 | P8: 1 | Q8: 2 | R8: 1 | S8: 1 | T8: 1 | U8: 5 | V8: 4 | W8: 5 | X8: 5 | Y8: 5 | Z8: 5 | AA8: 5 | AB8: 5 | AC8: 5 | AD8: 1 | AE8: 5 | AF8: 5 | AG8: 5 | AH8: 5 | AI8: 1 | AJ8: 1 | AK8: 1 | AL8: 5 | AM8: -
A9: Yes | B9: 8 | C9: 46245.545 | D9: ERและเปล | E9: สายวิชาชีพสาธารณสุข | F9: สายวิชาชีพสาธารณสุข | G9: 4 | H9: 4 | I9: 2 | J9: 3 | K9: 3 | L9: 3 | M9: 3 | N9: 3 | O9: 4 | P9: 1 | Q9: 2 | R9: 2 | S9: 3 | T9: 1 | U9: 4 | V9: 3 | W9: 3 | X9: 4 | Y9: 5 | Z9: 5 | AA9: 4 | AB9: 4 | AC9: 4 | AD9: 2 | AE9: 3 | AF9: 5 | AG9: 5 | AH9: 3 | AI9: 1 | AJ9: 2 | AK9: 1 | AL9: 5 | AM9: มีการติดตามความเสี่ยงสำคัญแต่ความเสี่ยงบางอย่างแก้ไม่ได้โดยระบบเช่นเรื่องคนไข้รอหมอนานช่วงต่อเวร เราไม่สารถแก้ไขในส่วนที่เป็นองค์กรแพทย์ได้โดยตรงแต่บางเรื่องสามารถเล่าให้ผอ.ฟังได้ในภาพรวม
A10: Yes | B10: 9 | C10: 46245.545 | D10: การเงิน | E10: สายสนับสนุนทั่วไป | F10: สายสนับสนุนทั่วไป | G10: 3 | H10: 3 | I10: 4 | J10: 3 | K10: 3 | L10: 2 | M10: 3 | N10: 4 | O10: 4 | P10: 3 | Q10: 3 | R10: 4 | S10: 4 | T10: 3 | U10: 4 | V10: 4 | W10: 4 | X10: 3 | Y10: 4 | Z10: 4 | AA10: 4 | AB10: 4 | AC10: 4 | AD10: 3 | AE10: 3 | AF10: 4 | AG10: 4 | AH10: 4 | AI10: 4 | AJ10: 3 | AK10: 3 | AL10: 3 | AM10: เพิ่มความปลอดภัยให้กับบุคลากรของรพ.
A11: Yes | B11: 10 | C11: 46245.547 | D11: IT | E11: สายสนับสนุนทางการแพทย์ | F11: สายสนับสนุนทางการแพทย์ | G11: 4 | H11: 5 | I11: 4 | J11: 3 | K11: 4 | L11: 3 | M11: 3 | N11: 4 | O11: 4 | P11: 2 | Q11: 4 | R11: 4 | S11: 3 | T11: 2 | U11: 4 | V11: 3 | W11: 4 | X11: 4 | Y11: 5 | Z11: 4 | AA11: 5 | AB11: 5 | AC11: 5 | AD11: 1 | AE11: 4 | AF11: 4 | AG11: 5 | AH11: 4 | AI11: 2 | AJ11: 2 | AK11: 3 | AL11: 2 | AM11: .
A12: Yes | B12: 11 | C12: 46245.552 | D12: IT | E12: สายสนับสนุนทั่วไป | F12: สายสนับสนุนทั่วไป | G12: 4 | H12: 5 | I12: 1 | J12: 3 | K12: 3 | L12: 2 | M12: 2 | N12: 4 | O12: 3 | P12: 3 | Q12: 3 | R12: 2 | S12: 4 | T12: 2 | U12: 5 | V12: 1 | W12: 5 | X12: 2 | Y12: 5 | Z12: 5 | AA12: 5 | AB12: 5 | AC12: 5 | AD12: 2 | AE12: 5 | AF12: 3 | AG12: 5 | AH12: 5 | AI12: 1 | AJ12: 1 | AK12: 1 | AL12: 5 | AM12: -
A13: Yes | B13: 12 | C13: 46245.556 | D13: OR | E13: สายวิชาชีพสาธารณสุข | F13: สายวิชาชีพสาธารณสุข | G13: 4 | H13: 4 | I13: 2 | J13: 3 | K13: 1 | L13: 2 | M13: 1 | N13: 4 | O13: 5 | P13: 1 | Q13: 3 | R13: 1 | S13: 2 | T13: 5 | U13: 3 | V13: 4 | W13: 3 | X13: 4 | Y13: 5 | Z13: 3 | AA13: 4 | AB13: 2 | AC13: 2 | AD13: 3 | AE13: 4 | AF13: 4 | AG13: 5 | AH13: 4 | AI13: 4 | AJ13: 4 | AK13: 4 | AL13: 4 | AM13: ดี
A14: Yes | B14: 13 | C14: 46245.56 | D14: HR | E14: สายสนับสนุนทั่วไป | F14: สายสนับสนุนทั่วไป | G14: 4 | H14: 4 | I14: 4 | J14: 4 | K14: 2 | L14: 3 | M14: 3 | N14: 4 | O14: 4 | P14: 3 | Q14: 3 | R14: 3 | S14: 3 | T14: 2 | U14: 4 | V14: 2 | W14: 4 | X14: 4 | Y14: 4 | Z14: 3 | AA14: 4 | AB14: 4 | AC14: 3 | AD14: 3 | AE14: 3 | AF14: 4 | AG14: 4 | AH14: 4 | AI14: 2 | AJ14: 1 | AK14: 2 | AL14: 4 | AM14: มีความปลอดภัยตามมาตรฐานโรงพยาบาล
A15: Yes | B15: 14 | C15: 46245.577 | D15: ช่างและสนาม | E15: สายสนับสนุนทั่วไป | F15: สายสนับสนุนทั่วไป | G15: 5 | H15: 5 | I15: 1 | J15: 4 | K15: 2 | L15: 3 | M15: 1 | N15: 5 | O15: 3 | P15: 1 | Q15: 1 | R15: 1 | S15: 4 | T15: 1 | U15: 4 | V15: 1 | W15: 4 | X15: 4 | Y15: 5 | Z15: 3 | AA15: 5 | AB15: 4 | AC15: 3 | AD15: 3 | AE15: 3 | AF15: 3 | AG15: 4 | AH15: 4 | AI15: 2 | AJ15: 2 | AK15: 1 | AL15: 4 | AM15: ช่วยกันสอดส่องดูแลและ สังเกตุสิ่งผิดปกติในโรงพยาบาล ที่จะก่อให้เกิดอันตรายต่อพนักงานและผู้รับบริการ
A16: Yes | B16: 15 | C16: 46245.578 | D16: เคหรักษ์ | E16: สายสนับสนุนทั่วไป | F16: สายสนับสนุนทั่วไป | G16: 3 | H16: 3 | I16: 3 | J16: 2 | K16: 3 | L16: 3 | M16: 3 | N16: 3 | O16: 2 | P16: 3 | Q16: 3 | R16: 3 | S16: 3 | T16: 3 | U16: 3 | V16: 3 | W16: 3 | X16: 3 | Y16: 3 | Z16: 3 | AA16: 3 | AB16: 3 | AC16: 3 | AD16: 3 | AE16: 3 | AF16: 3 | AG16: 3 | AH16: 3 | AI16: 3 | AJ16: 3 | AK16: 3 | AL16: 3 | AM16: ช่วยกันดูแลความปบอดภัย
... A59: Yes | B59: 58 | C59: 46249.502 | D59: IPD | E59: ผู้บริหาร | F59: ผู้บริหาร | G59: 5 | H59: 4 | I59: 2 | J59: 4 | K59: 4 | L59: 4 | M59: 3 | N59: 4 | O59: 4 | P59: 2 | Q59: 3 | R59: 3 | S59: 4 | T59: 3 | U59: 4 | V59: 2 | W59: 4 | X59: 4 | Y59: 4 | Z59: 4 | AA59: 4 | AB59: 4 | AC59: 4 | AD59: 3 | AE59: 4 | AF59: 5 | AG59: 5 | AH59: 5 | AI59: 5 | AJ59: 1 | AK59: 2 | AL59: 4 | AM59: -

Sheet Item_Metadata
A1: Item_Code | B1: Dimension | C1: Section | D1: Calculation_Type | E1: Negative_Item | F1: Positive_Rule | G1: Question_TH
A2: A1 | B2: 1. การทำงานเป็นทีม | C2: A | D2: Positive | E2: No | F2: 4 หรือ 5 | G2: ในหน่วยงานหรือพื้นที่ที่ท่านทำงานอยู่ ทุกคนทำงานร่วมกันเป็นทีมอย่างมีประสิทธิภาพ
A3: A8 | B3: 1. การทำงานเป็นทีม | C3: A | D3: Positive | E3: No | F3: 4 หรือ 5 | G3: ในช่วงเวลาที่มีภาระงานยุ่งมาก หรือยาก บุคลากรในหน่วยงานที่ท่านทำงานอยู่จะช่วยเหลือซึ่งกันและกันอย่างดี
A4: A9 | B4: 1. การทำงานเป็นทีม | C4: A | D4: Positive | E4: Yes | F4: 1 หรือ 2 | G4: ในหน่วยงานที่ท่านทำงานอยู่มีปัญหาเรื่องพฤติกรรมในการทำงานของบุคลากรที่ไม่เคารพซึ่งกันและกัน
A5: A2 | B5: 2. บุคลากรและพื้นที่การทำงาน | C5: A | D5: Positive | E5: No | F5: 4 หรือ 5 | G5: ในหน่วยงานหรือพื้นที่นี้มีจำนวนบุคลากรในการทำงานที่เพียงพอที่จะรับมือกับปริมาณงานหรือภาระงานของหน่วยงานที่กำหนด
A6: A3 | B6: 2. บุคลากรและพื้นที่การทำงาน | C6: A | D6: Positive | E6: Yes | F6: 1 หรือ 2 | G6: ในหน่วยงานที่ท่านทำงานมีบุคลากรที่ทำงานจำนวนชั่วโมงต่อเนื่องยาวนานมากกว่าที่เหมาะสมต่อการดูแลผู้ป่วยหรือผู้รับบริการได้ดี
A7: A5 | B7: 2. บุคลากรและพื้นที่การทำงาน | C7: A | D7: Positive | E7: Yes | F7: 1 หรือ 2 | G7: หน่วยงานที่ท่านทำงานอยู่ต้องอาศัยหรือพึ่งพาบุคลากรที่มาช่วยทำงานชั่วคราว บุคลากรที่หมุนเวียนมาทำงาน หรือที่ทำงานเฉพาะช่วงที่กำหนดเป็นครั้งๆ มากเกินไป
A8: A11 | B8: 2. บุคลากรและพื้นที่การทำงาน | C8: A | D8: Positive | E8: Yes | F8: 1 หรือ 2 | G8: หน่วยงานที่ท่านทำงานอยู่มักจะเร่งรีบในการทำงานมากเกินไปจนส่งผลกระทบในเชิงลบต่อความปลอดภัยของผู้ป่วยหรือผู้รับบริการ
A9: A4 | B9: 3. การเป็นองค์กรแห่งการเรียนรู้ มีการพัฒนาอย่างต่อเนื่อง | C9: A | D9: Positive | E9: No | F9: 4 หรือ 5 | G9: หน่วยงานที่ท่านทำงานอยู่มีการทบทวนกระบวนการทำงานอย่างสม่ำเสมอเพื่อพิจารณาว่าจำเป็นต้องมีการเปลี่ยนแปลงใดบ้างที่ควรปรับปรุงแก้ไขเพื่อความปลอดภัยของผู้ป่วยหรือผู้รับบริการ
A10: A12 | B10: 3. การเป็นองค์กรแห่งการเรียนรู้ มีการพัฒนาอย่างต่อเนื่อง | C10: A | D10: Positive | E10: No | F10: 4 หรือ 5 | G10: หน่วยงานที่ท่านทำงานอยู่มีการเปลี่ยนแปลงเพื่อเพิ่มความปลอดภัยให้กับผู้ป่วย/ผู้รับบริการ และมีการประเมินผลความปลอดภัยของผู้ป่วย/ผู้รับบริการว่าดีขึ้นอย่างไร
A11: A14 | B11: 3. การเป็นองค์กรแห่งการเรียนรู้ มีการพัฒนาอย่างต่อเนื่อง | C11: A | D11: Positive | E11: Yes | F11: 1 หรือ 2 | G11: หน่วยงานที่ท่านทำงานอยู่ปล่อยให้เกิดปัญหาเรื่องความปลอดภัยกับผู้ป่วย/ผู้รับบริการในเรื่องเดิมและเกิดขึ้นซ้ำๆ
A12: A6 | B12: 4. การตอบสนองต่อความคลาดเคลื่อน | C12: A | D12: Positive | E12: Yes | F12: 1 หรือ 2 | G12: ในหน่วยงานที่ท่านทำงานอยู่ บุคลากรรู้สึกว่าความผิดพลาดคลาดเคลื่อนที่อาจเกิดขึ้นในการทำงานจะถูกนำมากล่าวโทษกับตัวบุคคล
... A33: F6 | B33: 10. การส่งต่องานและแลกเปลี่ยนข้อมูล ในการเปลี่ยนผ่านระหว่างหน่วยงานหรือเวร | C33: F | D33: Positive | E33: No | F33: 4 หรือ 5 | G33: ระหว่างการเปลี่ยนเวรหรือกะการทำงานมีเวลาเพียงพอในการแลกเปลี่ยนและส่งต่อข้อมูลสำคัญการดูแลผู้ป่วย/ผู้รับบริการ ที่สำคัญทั้งหมด

Sheet Unit_Index
A1: Scope | B1: กลุ่มตามสายงาน | C1: กลุ่มงาน | D1: พื้นที่ปฏิบัติงาน | E1: จำนวนผู้ตอบ
A2: ภาพรวม | B2: ภาพรวม | C2: ภาพรวม | D2: ภาพรวม | E2: 58
A3: ภาพรวมทุกกลุ่ม | B3: ภาพรวม | C3: ภาพรวมทุกกลุ่ม | D3: การเงิน | E3: 3
A4: ภาพรวมทุกกลุ่ม | B4: ภาพรวม | C4: ภาพรวมทุกกลุ่ม | D4: เคหรักษ์ | E4: 2
A5: ภาพรวมทุกกลุ่ม | B5: ภาพรวม | C5: ภาพรวมทุกกลุ่ม | D5: จ่ายกลาง | E5: 1
A6: ภาพรวมทุกกลุ่ม | B6: ภาพรวม | C6: ภาพรวมทุกกลุ่ม | D6: ช่างและสนาม | E6: 4
A7: ภาพรวมทุกกลุ่ม | B7: ภาพรวม | C7: ภาพรวมทุกกลุ่ม | D7: ผู้ป่วยสัมพันธ์ | E7: 4
A8: ภาพรวมทุกกลุ่ม | B8: ภาพรวม | C8: ภาพรวมทุกกลุ่ม | D8: ฝ่ายการพยาบาล | E8: 2
A9: ภาพรวมทุกกลุ่ม | B9: ภาพรวม | C9: ภาพรวมทุกกลุ่ม | D9: โภชนาการ | E9: 1
A10: ภาพรวมทุกกลุ่ม | B10: ภาพรวม | C10: ภาพรวมทุกกลุ่ม | D10: ยานพาหนะ | E10: 1
A11: ภาพรวมทุกกลุ่ม | B11: ภาพรวม | C11: ภาพรวมทุกกลุ่ม | D11: สื่อสารการตลาด | E11: 1
A12: ภาพรวมทุกกลุ่ม | B12: ภาพรวม | C12: ภาพรวมทุกกลุ่ม | D12: ห้องยา | E12: 6
A13: ภาพรวมทุกกลุ่ม | B13: ภาพรวม | C13: ภาพรวมทุกกลุ่ม | D13: ห้องแลป | E13: 2
... A48: สายสนับสนุนทางการแพทย์ | B48: สายสนับสนุนทางการแพทย์ | C48: สายสนับสนุนทางการแพทย์ | D48: IT | E48: 1

Sheet HSCS2569
A1: Dimension | B1: Item | C1: ภาพรวม | D1: ภาพรวม | V1: ผู้บริหาร | W1: สายวิชาชีพสาธารณสุข | AB1: สายสนับสนุนทั่วไป | AN1: สายสนับสนุนทางการแพทย์
D2: ภาพรวมทุกกลุ่ม | V2: ผู้บริหาร | W2: สายวิชาชีพสาธารณสุข | AB2: สายสนับสนุนทั่วไป | AN2: สายสนับสนุนทางการแพทย์
D3: การเงิน | E3: เคหรักษ์ | F3: จ่ายกลาง | G3: ช่างและสนาม | H3: ผู้ป่วยสัมพันธ์ | I3: ฝ่ายการพยาบาล | J3: โภชนาการ | K3: ยานพาหนะ | L3: สื่อสารการตลาด | M3: ห้องยา | N3: ห้องแลป | O3: ห้องเอ็กซเรย์ | P3: ERและเปล | Q3: HR | R3: ICU | S3: IPD | T3: IT | U3: OR | V3: IPD | W3: ฝ่ายการพยาบาล | X3: ERและเปล | Y3: ICU | Z3: IPD | AA3: OR | AB3: การเงิน | AC3: เคหรักษ์ | AD3: จ่ายกลาง | AE3: ช่างและสนาม | AF3: ผู้ป่วยสัมพันธ์ | AG3: ยานพาหนะ | AH3: สื่อสารการตลาด | AI3: ERและเปล | AJ3: HR | AK3: ICU | AL3: IPD | AM3: IT | AN3: ผู้ป่วยสัมพันธ์ | AO3: ฝ่ายการพยาบาล | AP3: โภชนาการ | AQ3: ห้องยา | AR3: ห้องแลป | AS3: ห้องเอ็กซเรย์ | AT3: ERและเปล | AU3: ICU | AV3: IPD | AW3: IT
A4: 1. การทำงานเป็นทีม | B4: A1. ในหน่วยงานหรือพื้นที่ที่ท่านทำงานอยู่ ทุกคนทำงานร่วมกันเป็นทีมอย่างมีประสิทธิภาพ | C4: =IFERROR(100*COUNTIFS(Raw_Data!$G$2:$G$59,">=4",Raw_Data!$G$2:$G$59,"<=5",Raw_Data!$A$2:$A$59,"Yes")/COUNTIFS(Raw_Data!$G$2:$G$59,">=1",Raw_Data!$G$2:$G$59,"<=5",Raw_Data!$A$2:$A$59,"Yes"),"") -> 63.793103 | D4: =IFERROR(100*COUNTIFS(Raw_Data!$G$2:$G$59,">=4",Raw_Data!$G$2:$G$59,"<=5",Raw_Data!$A$2:$A$59,"Yes",Raw_Data!$D$2:$D$59,"การเงิน")/COUNTIFS(Raw_Data!$G$2:$G$59,">=1",Raw_Data!$G$2:$G$59,"<=5",Raw_Data!$A$2:$A$59,"Yes",Raw_Data!$D$2:$D$59,"การเงิน"),"") -> 33.333333 | E4: =IFERROR(100*COUNTIFS(Raw_Data!$G$2:$G$59,">=4",Raw_Data!$G$2:$G$59,"<=5",Raw_Data!$A$2:$A$59,"Yes",Raw_Data!$D$2:$D$59,"เคหรักษ์")/COUNTIFS(Raw_Data!$G$2:$G$59,">=1",Raw_Data!$G$2:$G$59,"<=5",Raw_Data!$A$2:$A$59,"Yes",Raw_Data!$D$2:$D$59,"เคหรักษ์"),"") -> 0 | F4: =IFERROR(100*COUNTIFS(Raw_Data!$G$2:$G$59,">=4",Raw_Data!$G$2:$G$59,"<=5",Raw_Data!$A$2:$A$59,"Yes",Raw_Data!$D$2:$D$59,"จ่ายกลาง")/COUNTIFS(Raw_Data!$G$2:$G$59,">=1",Raw_Data!$G$2:$G$59,"<=5",Raw_Data!$A$2:$A$59,"Yes",Raw_Data!$D$2:$D$59,"จ่ายกลาง"),"") -> 100 | G4: =IFERROR(100*COUNTIFS(Raw_Data!$G$2:$G$59,">=4",Raw_Data!$G$2:$G$59,"<=5",Raw_Data!$A$2:$A$59,"Yes",Raw_Data!$D$2:$D$59,"ช่างและสนาม")/COUNTIFS(Raw_Data!$G$2:$G$59,">=1",Raw_Data!$G$2:$G$59,"<=5",Raw_Data!$A$2:$A$59,"Yes",Raw_Data!$D$2:$D$59,"ช่างและสนาม"),"") -> 50 | H4: =IFERROR(100*COUNTIFS(Raw_Data!$G$2:$G$59,">=4",Raw_Data!$G$2:$G$59,"<=5",Raw_Data!$A$2:$A$59,"Yes",Raw_Data!$D$2:$D$59,"ผู้ป่วยสัมพันธ์")/COUNTIFS(Raw_Data!$G$2:$G$59,">=1",Raw_Data!$G$2:$G$59,"<=5",Raw_Data!$A$2:$A$59,"Yes",Raw_Data!$D$2:$D$59,"ผู้ป่วยสัมพันธ์"),"") -> 75 | I4: =IFERROR(100*COUNTIFS(Raw_Data!$G$2:$G$59,">=4",Raw_Data!$G$2:$G$59,"<=5",Raw_Data!$A$2:$A$59,"Yes",Raw_Data!$D$2:$D$59,"ฝ่ายการพยาบาล")/COUNTIFS(Raw_Data!$G$2:$G$59,">=1",Raw_Data!$G$2:$G$59,"<=5",Raw_Data!$A$2:$A$59,"Yes",Raw_Data!$D$2:$D$59,"ฝ่ายการพยาบาล"),"") -> 50 | J4: =IFERROR(100*COUNTIFS(Raw_Data!$G$2:$G$59,">=4",Raw_Data!$G$2:$G$59,"<=5",Raw_Data!$A$2:$A$59,"Yes",Raw_Data!$D$2:$D$59,"โภชนาการ")/COUNTIFS(Raw_Data!$G$2:$G$59,">=1",Raw_Data!$G$2:$G$59,"<=5",Raw_Data!$A$2:$A$59,"Yes",Raw_Data!$D$2:$D$59,"โภชนาการ"),"") -> 100 | K4: =IFERROR(100*COUNTIFS(Raw_Data!$G$2:$G$59,">=4",Raw_Data!$G$2:$G$59,"<=5",Raw_Data!$A$2:$A$59,"Yes",Raw_Data!$D$2:$D$59,"ยานพาหนะ")/COUNTIFS(Raw_Data!$G$2:$G$59,">=1",Raw_Data!$G$2:$G$59,"<=5",Raw_Data!$A$2:$A$59,"Yes",Raw_Data!$D$2:$D$59,"ยานพาหนะ"),"") -> 0 | L4: =IFERROR(100*COUNTIFS(Raw_Data!$G$2:$G$59,">=4",Raw_Data!$G$2:$G$59,"<=5",Raw_Data!$A$2:$A$59,"Yes",Raw_Data!$D$2:$D$59,"สื่อสารการตลาด")/COUNTIFS(Raw_Data!$G$2:$G$59,">=1",Raw_Data!$G$2:$G$59,"<=5",Raw_Data!$A$2:$A$59,"Yes",Raw_Data!$D$2:$D$59,"สื่อสารการตลาด"),"") -> 0 | M4: =IFERROR(100*COUNTIFS(Raw_Data!$G$2:$G$59,">=4",Raw_Data!$G$2:$G$59,"<=5",Raw_Data!$A$2:$A$59,"Yes",Raw_Data!$D$2:$D$59,"ห้องยา")/COUNTIFS(Raw_Data!$G$2:$G$59,">=1",Raw_Data!$G$2:$G$59,"<=5",Raw_Data!$A$2:$A$59,"Yes",Raw_Data!$D$2:$D$59,"ห้องยา"),"") -> 100 | N4: =IFERROR(100*COUNTIFS(Raw_Data!$G$2:$G$59,">=4",Raw_Data!$G$2:$G$59,"<=5",Raw_Data!$A$2:$A$59,"Yes",Raw_Data!$D$2:$D$59,"ห้องแลป")/COUNTIFS(Raw_Data!$G$2:$G$59,">=1",Raw_Data!$G$2:$G$59,"<=5",Raw_Data!$A$2:$A$59,"Yes",Raw_Data!$D$2:$D$59,"ห้องแลป"),"") -> 50 | O4: =IFERROR(100*COUNTIFS(Raw_Data!$G$2:$G$59,">=4",Raw_Data!$G$2:$G$59,"<=5",Raw_Data!$A$2:$A$59,"Yes",Raw_Data!$D$2:$D$59,"ห้องเอ็กซเรย์")/COUNTIFS(Raw_Data!$G$2:$G$59,">=1",Raw_Data!$G$2:$G$59,"<=5",Raw_Data!$A$2:$A$59,"Yes",Raw_Data!$D$2:$D$59,"ห้องเอ็กซเรย์"),"") -> 100 | P4: =IFERROR(100*COUNTIFS(Raw_Data!$G$2:$G$59,">=4",Raw_Data!$G$2:$G$59,"<=5",Raw_Data!$A$2:$A$59,"Yes",Raw_Data!$D$2:$D$59,"ERและเปล")/COUNTIFS(Raw_Data!$G$2:$G$59,">=1",Raw_Data!$G$2:$G$59,"<=5",Raw_Data!$A$2:$A$59,"Yes",Raw_Data!$D$2:$D$59,"ERและเปล"),"") -> 27.272727 | Q4: =IFERROR(100*COUNTIFS(Raw_Data!$G$2:$G$59,">=4",Raw_Data!$G$2:$G$59,"<=5",Raw_Data!$A$2:$A$59,"Yes",Raw_Data!$D$2:$D$59,"HR")/COUNTIFS(Raw_Data!$G$2:$G$59,">=1",Raw_Data!$G$2:$G$59,"<=5",Raw_Data!$A$2:$A$59,"Yes",Raw_Data!$D$2:$D$59,"HR"),"") -> 100 | R4: =IFERROR(100*COUNTIFS(Raw_Data!$G$2:$G$59,">=4",Raw_Data!$G$2:$G$59,"<=5",Raw_Data!$A$2:$A$59,"Yes",Raw_Data!$D$2:$D$59,"ICU")/COUNTIFS(Raw_Data!$G$2:$G$59,">=1",Raw_Data!$G$2:$G$59,"<=5",Raw_Data!$A$2:$A$59,"Yes",Raw_Data!$D$2:$D$59,"ICU"),"") -> 100 | S4: =IFERROR(100*COUNTIFS(Raw_Data!$G$2:$G$59,">=4",Raw_Data!$G$2:$G$59,"<=5",Raw_Data!$A$2:$A$59,"Yes",Raw_Data!$D$2:$D$59,"IPD")/COUNTIFS(Raw_Data!$G$2:$G$59,">=1",Raw_Data!$G$2:$G$59,"<=5",Raw_Data!$A$2:$A$59,"Yes",Raw_Data!$D$2:$D$59,"IPD"),"") -> 66.666667 | T4: =IFERROR(100*COUNTIFS(Raw_Data!$G$2:$G$59,">=4",Raw_Data!$G$2:$G$59,"<=5",Raw_Data!$A$2:$A$59,"Yes",Raw_Data!$D$2:$D$59,"IT")/COUNTIFS(Raw_Data!$G$2:$G$59,">=1",Raw_Data!$G$2:$G$59,"<=5",Raw_Data!$A$2:$A$59,"Yes",Raw_Data!$D$2:$D$59,"IT"),"") -> 100 | U4: =IFERROR(100*COUNTIFS(Raw_Data!$G$2:$G$59,">=4",Raw_Data!$G$2:$G$59,"<=5",Raw_Data!$A$2:$A$59,"Yes",Raw_Data!$D$2:$D$59,"OR")/COUNTIFS(Raw_Data!$G$2:$G$59,">=1",Raw_Data!$G$2:$G$59,"<=5",Raw_Data!$A$2:$A$59,"Yes",Raw_Data!$D$2:$D$59,"OR"),"") -> 100 | V4: =IFERROR(100*COUNTIFS(Raw_Data!$G$2:$G$59,">=4",Raw_Data!$G$2:$G$59,"<=5",Raw_Data!$A$2:$A$59,"Yes",Raw_Data!$D$2:$D$59,"IPD",Raw_Data!$E$2:$E$59,"ผู้บริหาร")/COUNTIFS(Raw_Data!$G$2:$G$59,">=1",Raw_Data!$G$2:$G$59,"<=5",Raw_Data!$A$2:$A$59,"Yes",Raw_Data!$D$2:$D$59,"IPD",Raw_Data!$E$2:$E$59,"ผู้บริหาร"),"") -> 100 | W4: =IFERROR(100*COUNTIFS(Raw_Data!$G$2:$G$59,">=4",Raw_Data!$G$2:$G$59,"<=5",Raw_Data!$A$2:$A$59,"Yes",Raw_Data!$D$2:$D$59,"ฝ่ายการพยาบาล",Raw_Data!$E$2:$E$59,"สายวิชาชีพสาธารณสุข")/COUNTIFS(Raw_Data!$G$2:$G$59,">=1",Raw_Data!$G$2:$G$59,"<=5",Raw_Data!$A$2:$A$59,"Yes",Raw_Data!$D$2:$D$59,"ฝ่ายการพยาบาล",Raw_Data!$E$2:$E$59,"สายวิชาชีพสาธารณสุข"),"") -> 0 | X4: =IFERROR(100*COUNTIFS(Raw_Data!$G$2:$G$59,">=4",Raw_Data!$G$2:$G$59,"<=5",Raw_Data!$A$2:$A$59,"Yes",Raw_Data!$D$2:$D$59,"ERและเปล",Raw_Data!$E$2:$E$59,"สายวิชาชีพสาธารณสุข")/COUNTIFS(Raw_Data!$G$2:$G$59,">=1",Raw_Data!$G$2:$G$59,"<=5",Raw_Data!$A$2:$A$59,"Yes",Raw_Data!$D$2:$D$59,"ERและเปล",Raw_Data!$E$2:$E$59,"สายวิชาชีพสาธารณสุข"),"") -> 28.571429 | Y4: =IFERROR(100*COUNTIFS(Raw_Data!$G$2:$G$59,">=4",Raw_Data!$G$2:$G$59,"<=5",Raw_Data!$A$2:$A$59,"Yes",Raw_Data!$D$2:$D$59,"ICU",Raw_Data!$E$2:$E$59,"สายวิชาชีพสาธารณสุข")/COUNTIFS(Raw_Data!$G$2:$G$59,">=1",Raw_Data!$G$2:$G$59,"<=5",Raw_Data!$A$2:$A$59,"Yes",Raw_Data!$D$2:$D$59,"ICU",Raw_Data!$E$2:$E$59,"สายวิชาชีพสาธารณสุข"),"") -> 100 | Z4: =IFERROR(100*COUNTIFS(Raw_Data!$G$2:$G$59,">=4",Raw_Data!$G$2:$G$59,"<=5",Raw_Data!$A$2:$A$59,"Yes",Raw_Data!$D$2:$D$59,"IPD",Raw_Data!$E$2:$E$59,"สายวิชาชีพสาธารณสุข")/COUNTIFS(Raw_Data!$G$2:$G$59,">=1",Raw_Data!$G$2:$G$59,"<=5",Raw_Data!$A$2:$A$59,"Yes",Raw_Data!$D$2:$D$59,"IPD",Raw_Data!$E$2:$E$59,"สายวิชาชีพสาธารณสุข"),"") -> 100 | AA4: =IFERROR(100*COUNTIFS(Raw_Data!$G$2:$G$59,">=4",Raw_Data!$G$2:$G$59,"<=5",Raw_Data!$A$2:$A$59,"Yes",Raw_Data!$D$2:$D$59,"OR",Raw_Data!$E$2:$E$59,"สายวิชาชีพสาธารณสุข")/COUNTIFS(Raw_Data!$G$2:$G$59,">=1",Raw_Data!$G$2:$G$59,"<=5",Raw_Data!$A$2:$A$59,"Yes",Raw_Data!$D$2:$D$59,"OR",Raw_Data!$E$2:$E$59,"สายวิชาชีพสาธารณสุข"),"") -> 100 | AB4: =IFERROR(100*COUNTIFS(Raw_Data!$G$2:$G$59,">=4",Raw_Data!$G$2:$G$59,"<=5",Raw_Data!$A$2:$A$59,"Yes",Raw_Data!$D$2:$D$59,"การเงิน",Raw_Data!$E$2:$E$59,"สายสนับสนุนทั่วไป")/COUNTIFS(Raw_Data!$G$2:$G$59,">=1",Raw_Data!$G$2:$G$59,"<=5",Raw_Data!$A$2:$A$59,"Yes",Raw_Data!$D$2:$D$59,"การเงิน",Raw_Data!$E$2:$E$59,"สายสนับสนุนทั่วไป"),"") -> 33.333333 | AC4: =IFERROR(100*COUNTIFS(Raw_Data!$G$2:$G$59,">=4",Raw_Data!$G$2:$G$59,"<=5",Raw_Data!$A$2:$A$59,"Yes",Raw_Data!$D$2:$D$59,"เคหรักษ์",Raw_Data!$E$2:$E$59,"สายสนับสนุนทั่วไป")/COUNTIFS(Raw_Data!$G$2:$G$59,">=1",Raw_Data!$G$2:$G$59,"<=5",Raw_Data!$A$2:$A$59,"Yes",Raw_Data!$D$2:$D$59,"เคหรักษ์",Raw_Data!$E$2:$E$59,"สายสนับสนุนทั่วไป"),"") -> 0 | AD4: =IFERROR(100*COUNTIFS(Raw_Data!$G$2:$G$59,">=4",Raw_Data!$G$2:$G$59,"<=5",Raw_Data!$A$2:$A$59,"Yes",Raw_Data!$D$2:$D$59,"จ่ายกลาง",Raw_Data!$E$2:$E$59,"สายสนับสนุนทั่วไป")/COUNTIFS(Raw_Data!$G$2:$G$59,">=1",Raw_Data!$G$2:$G$59,"<=5",Raw_Data!$A$2:$A$59,"Yes",Raw_Data!$D$2:$D$59,"จ่ายกลาง",Raw_Data!$E$2:$E$59,"สายสนับสนุนทั่วไป"),"") -> 100 | AE4: =IFERROR(100*COUNTIFS(Raw_Data!$G$2:$G$59,">=4",Raw_Data!$G$2:$G$59,"<=5",Raw_Data!$A$2:$A$59,"Yes",Raw_Data!$D$2:$D$59,"ช่างและสนาม",Raw_Data!$E$2:$E$59,"สายสนับสนุนทั่วไป")/COUNTIFS(Raw_Data!$G$2:$G$59,">=1",Raw_Data!$G$2:$G$59,"<=5",Raw_Data!$A$2:$A$59,"Yes",Raw_Data!$D$2:$D$59,"ช่างและสนาม",Raw_Data!$E$2:$E$59,"สายสนับสนุนทั่วไป"),"") -> 50 | AF4: =IFERROR(100*COUNTIFS(Raw_Data!$G$2:$G$59,">=4",Raw_Data!$G$2:$G$59,"<=5",Raw_Data!$A$2:$A$59,"Yes",Raw_Data!$D$2:$D$59,"ผู้ป่วยสัมพันธ์",Raw_Data!$E$2:$E$59,"สายสนับสนุนทั่วไป")/COUNTIFS(Raw_Data!$G$2:$G$59,">=1",Raw_Data!$G$2:$G$59,"<=5",Raw_Data!$A$2:$A$59,"Yes",Raw_Data!$D$2:$D$59,"ผู้ป่วยสัมพันธ์",Raw_Data!$E$2:$E$59,"สายสนับสนุนทั่วไป"),"") -> 0 | AG4: =IFERROR(100*COUNTIFS(Raw_Data!$G$2:$G$59,">=4",Raw_Data!$G$2:$G$59,"<=5",Raw_Data!$A$2:$A$59,"Yes",Raw_Data!$D$2:$D$59,"ยานพาหนะ",Raw_Data!$E$2:$E$59,"สายสนับสนุนทั่วไป")/COUNTIFS(Raw_Data!$G$2:$G$59,">=1",Raw_Data!$G$2:$G$59,"<=5",Raw_Data!$A$2:$A$59,"Yes",Raw_Data!$D$2:$D$59,"ยานพาหนะ",Raw_Data!$E$2:$E$59,"สายสนับสนุนทั่วไป"),"") -> 0 | AH4: =IFERROR(100*COUNTIFS(Raw_Data!$G$2:$G$59,">=4",Raw_Data!$G$2:$G$59,"<=5",Raw_Data!$A$2:$A$59,"Yes",Raw_Data!$D$2:$D$59,"สื่อสารการตลาด",Raw_Data!$E$2:$E$59,"สายสนับสนุนทั่วไป")/COUNTIFS(Raw_Data!$G$2:$G$59,">=1",Raw_Data!$G$2:$G$59,"<=5",Raw_Data!$A$2:$A$59,"Yes",Raw_Data!$D$2:$D$59,"สื่อสารการตลาด",Raw_Data!$E$2:$E$59,"สายสนับสนุนทั่วไป"),"") -> 0 | AI4: =IFERROR(100*COUNTIFS(Raw_Data!$G$2:$G$59,">=4",Raw_Data!$G$2:$G$59,"<=5",Raw_Data!$A$2:$A$59,"Yes",Raw_Data!$D$2:$D$59,"ERและเปล",Raw_Data!$E$2:$E$59,"สายสนับสนุนทั่วไป")/COUNTIFS(Raw_Data!$G$2:$G$59,">=1",Raw_Data!$G$2:$G$59,"<=5",Raw_Data!$A$2:$A$59,"Yes",Raw_Data!$D$2:$D$59,"ERและเปล",Raw_Data!$E$2:$E$59,"สายสนับสนุนทั่วไป"),"") -> 33.333333 | AJ4: =IFERROR(100*COUNTIFS(Raw_Data!$G$2:$G$59,">=4",Raw_Data!$G$2:$G$59,"<=5",Raw_Data!$A$2:$A$59,"Yes",Raw_Data!$D$2:$D$59,"HR",Raw_Data!$E$2:$E$59,"สายสนับสนุนทั่วไป")/COUNTIFS(Raw_Data!$G$2:$G$59,">=1",Raw_Data!$G$2:$G$59,"<=5",Raw_Data!$A$2:$A$59,"Yes",Raw_Data!$D$2:$D$59,"HR",Raw_Data!$E$2:$E$59,"สายสนับสนุนทั่วไป"),"") -> 100 | AK4: =IFERROR(100*COUNTIFS(Raw_Data!$G$2:$G$59,">=4",Raw_Data!$G$2:$G$59,"<=5",Raw_Data!$A$2:$A$59,"Yes",Raw_Data!$D$2:$D$59,"ICU",Raw_Data!$E$2:$E$59,"สายสนับสนุนทั่วไป")/COUNTIFS(Raw_Data!$G$2:$G$59,">=1",Raw_Data!$G$2:$G$59,"<=5",Raw_Data!$A$2:$A$59,"Yes",Raw_Data!$D$2:$D$59,"ICU",Raw_Data!$E$2:$E$59,"สายสนับสนุนทั่วไป"),"") -> 100 | AL4: =IFERROR(100*COUNTIFS(Raw_Data!$G$2:$G$59,">=4",Raw_Data!$G$2:$G$59,"<=5",Raw_Data!$A$2:$A$59,"Yes",Raw_Data!$D$2:$D$59,"IPD",Raw_Data!$E$2:$E$59,"สายสนับสนุนทั่วไป")/COUNTIFS(Raw_Data!$G$2:$G$59,">=1",Raw_Data!$G$2:$G$59,"<=5",Raw_Data!$A$2:$A$59,"Yes",Raw_Data!$D$2:$D$59,"IPD",Raw_Data!$E$2:$E$59,"สายสนับสนุนทั่วไป"),"") -> 0 | AM4: =IFERROR(100*COUNTIFS(Raw_Data!$G$2:$G$59,">=4",Raw_Data!$G$2:$G$59,"<=5",Raw_Data!$A$2:$A$59,"Yes",Raw_Data!$D$2:$D$59,"IT",Raw_Data!$E$2:$E$59,"สายสนับสนุนทั่วไป")/COUNTIFS(Raw_Data!$G$2:$G$59,">=1",Raw_Data!$G$2:$G$59,"<=5",Raw_Data!$A$2:$A$59,"Yes",Raw_Data!$D$2:$D$59,"IT",Raw_Data!$E$2:$E$59,"สายสนับสนุนทั่วไป"),"") -> 100 | AN4: =IFERROR(100*COUNTIFS(Raw_Data!$G$2:$G$59,">=4",Raw_Data!$G$2:$G$59,"<=5",Raw_Data!$A$2:$A$59,"Yes",Raw_Data!$D$2:$D$59,"ผู้ป่วยสัมพันธ์",Raw_Data!$E$2:$E$59,"สายสนับสนุนทางการแพทย์")/COUNTIFS(Raw_Data!$G$2:$G$59,">=1",Raw_Data!$G$2:$G$59,"<=5",Raw_Data!$A$2:$A$59,"Yes",Raw_Data!$D$2:$D$59,"ผู้ป่วยสัมพันธ์",Raw_Data!$E$2:$E$59,"สายสนับสนุนทางการแพทย์"),"") -> 100 | AO4: =IFERROR(100*COUNTIFS(Raw_Data!$G$2:$G$59,">=4",Raw_Data!$G$2:$G$59,"<=5",Raw_Data!$A$2:$A$59,"Yes",Raw_Data!$D$2:$D$59,"ฝ่ายการพยาบาล",Raw_Data!$E$2:$E$59,"สายสนับสนุนทางการแพทย์")/COUNTIFS(Raw_Data!$G$2:$G$59,">=1",Raw_Data!$G$2:$G$59,"<=5",Raw_Data!$A$2:$A$59,"Yes",Raw_Data!$D$2:$D$59,"ฝ่ายการพยาบาล",Raw_Data!$E$2:$E$59,"สายสนับสนุนทางการแพทย์"),"") -> 100 | AP4: =IFERROR(100*COUNTIFS(Raw_Data!$G$2:$G$59,">=4",Raw_Data!$G$2:$G$59,"<=5",Raw_Data!$A$2:$A$59,"Yes",Raw_Data!$D$2:$D$59,"โภชนาการ",Raw_Data!$E$2:$E$59,"สายสนับสนุนทางการแพทย์")/COUNTIFS(Raw_Data!$G$2:$G$59,">=1",Raw_Data!$G$2:$G$59,"<=5",Raw_Data!$A$2:$A$59,"Yes",Raw_Data!$D$2:$D$59,"โภชนาการ",Raw_Data!$E$2:$E$59,"สายสนับสนุนทางการแพทย์"),"") -> 100 | AQ4: =IFERROR(100*COUNTIFS(Raw_Data!$G$2:$G$59,">=4",Raw_Data!$G$2:$G$59,"<=5",Raw_Data!$A$2:$A$59,"Yes",Raw_Data!$D$2:$D$59,"ห้องยา",Raw_Data!$E$2:$E$59,"สายสนับสนุนทางการแพทย์")/COUNTIFS(Raw_Data!$G$2:$G$59,">=1",Raw_Data!$G$2:$G$59,"<=5",Raw_Data!$A$2:$A$59,"Yes",Raw_Data!$D$2:$D$59,"ห้องยา",Raw_Data!$E$2:$E$59,"สายสนับสนุนทางการแพทย์"),"") -> 100 | AR4: =IFERROR(100*COUNTIFS(Raw_Data!$G$2:$G$59,">=4",Raw_Data!$G$2:$G$59,"<=5",Raw_Data!$A$2:$A$59,"Yes",Raw_Data!$D$2:$D$59,"ห้องแลป",Raw_Data!$E$2:$E$59,"สายสนับสนุนทางการแพทย์")/COUNTIFS(Raw_Data!$G$2:$G$59,">=1",Raw_Data!$G$2:$G$59,"<=5",Raw_Data!$A$2:$A$59,"Yes",Raw_Data!$D$2:$D$59,"ห้องแลป",Raw_Data!$E$2:$E$59,"สายสนับสนุนทางการแพทย์"),"") -> 50 | AS4: =IFERROR(100*COUNTIFS(Raw_Data!$G$2:$G$59,">=4",Raw_Data!$G$2:$G$59,"<=5",Raw_Data!$A$2:$A$59,"Yes",Raw_Data!$D$2:$D$59,"ห้องเอ็กซเรย์",Raw_Data!$E$2:$E$59,"สายสนับสนุนทางการแพทย์")/COUNTIFS(Raw_Data!$G$2:$G$59,">=1",Raw_Data!$G$2:$G$59,"<=5",Raw_Data!$A$2:$A$59,"Yes",Raw_Data!$D$2:$D$59,"ห้องเอ็กซเรย์",Raw_Data!$E$2:$E$59,"สายสนับสนุนทางการแพทย์"),"") -> 100 | AT4: =IFERROR(100*COUNTIFS(Raw_Data!$G$2:$G$59,">=4",Raw_Data!$G$2:$G$59,"<=5",Raw_Data!$A$2:$A$59,"Yes",Raw_Data!$D$2:$D$59,"ERและเปล",Raw_Data!$E$2:$E$59,"สายสนับสนุนทางการแพทย์")/COUNTIFS(Raw_Data!$G$2:$G$59,">=1",Raw_Data!$G$2:$G$59,"<=5",Raw_Data!$A$2:$A$59,"Yes",Raw_Data!$D$2:$D$59,"ERและเปล",Raw_Data!$E$2:$E$59,"สายสนับสนุนทางการแพทย์"),"") -> 0 | AU4: =IFERROR(100*COUNTIFS(Raw_Data!$G$2:$G$59,">=4",Raw_Data!$G$2:$G$59,"<=5",Raw_Data!$A$2:$A$59,"Yes",Raw_Data!$D$2:$D$59,"ICU",Raw_Data!$E$2:$E$59,"สายสนับสนุนทางการแพทย์")/COUNTIFS(Raw_Data!$G$2:$G$59,">=1",Raw_Data!$G$2:$G$59,"<=5",Raw_Data!$A$2:$A$59,"Yes",Raw_Data!$D$2:$D$59,"ICU",Raw_Data!$E$2:$E$59,"สายสนับสนุนทางการแพทย์"),"") -> 100 | AV4: =IFERROR(100*COUNTIFS(Raw_Data!$G$2:$G$59,">=4",Raw_Data!$G$2:$G$59,"<=5",Raw_Data!$A$2:$A$59,"Yes",Raw_Data!$D$2:$D$59,"IPD",Raw_Data!$E$2:$E$59,"สายสนับสนุนทางการแพทย์")/COUNTIFS(Raw_Data!$G$2:$G$59,">=1",Raw_Data!$G$2:$G$59,"<=5",Raw_Data!$A$2:$A$59,"Yes",Raw_Data!$D$2:$D$59,"IPD",Raw_Data!$E$2:$E$59,"สายสนับสนุนทางการแพทย์"),"") -> 50 | AW4: =IFERROR(100*COUNTIFS(Raw_Data!$G$2:$G$59,">=4",Raw_Data!$G$2:$G$59,"<=5",Raw_Data!$A$2:$A$59,"Yes",Raw_Data!$D$2:$D$59,"IT",Raw_Data!$E$2:$E$59,"สายสนับสนุนทางการแพทย์")/COUNTIFS(Raw_Data!$G$2:$G$59,">=1",Raw_Data!$G$2:$G$59,"<=5",Raw_Data!$A$2:$A$59,"Yes",Raw_Data!$D$2:$D$59,"IT",Raw_Data!$E$2:$E$59,"สายสนับสนุนทางการแพทย์"),"") -> 100
B5: A8. ในช่วงเวลาที่มีภาระงานยุ่งมาก หรือยาก บุคลากรในหน่วยงานที่ท่านทำงานอยู่จะช่วยเหลือซึ่งกันและกันอย่างดี | C5: =IFERROR(100*COUNTIFS(Raw_Data!$H$2:$H$59,">=4",Raw_Data!$H$2:$H$59,"<=5",Raw_Data!$A$2:$A$59,"Yes")/COUNTIFS(Raw_Data!$H$2:$H$59,">=1",Raw_Data!$H$2:$H$59,"<=5",Raw_Data!$A$2:$A$59,"Yes"),"") -> 62.068966 | D5: =IFERROR(100*COUNTIFS(Raw_Data!$H$2:$H$59,">=4",Raw_Data!$H$2:$H$59,"<=5",Raw_Data!$A$2:$A$59,"Yes",Raw_Data!$D$2:$D$59,"การเงิน")/COUNTIFS(Raw_Data!$H$2:$H$59,">=1",Raw_Data!$H$2:$H$59,"<=5",Raw_Data!$A$2:$A$59,"Yes",Raw_Data!$D$2:$D$59,"การเงิน"),"") -> 33.333333 | E5: =IFERROR(100*COUNTIFS(Raw_Data!$H$2:$H$59,">=4",Raw_Data!$H$2:$H$59,"<=5",Raw_Data!$A$2:$A$59,"Yes",Raw_Data!$D$2:$D$59,"เคหรักษ์")/COUNTIFS(Raw_Data!$H$2:$H$59,">=1",Raw_Data!$H$2:$H$59,"<=5",Raw_Data!$A$2:$A$59,"Yes",Raw_Data!$D$2:$D$59,"เคหรักษ์"),"") -> 0 | F5: =IFERROR(100*COUNTIFS(Raw_Data!$H$2:$H$59,">=4",Raw_Data!$H$2:$H$59,"<=5",Raw_Data!$A$2:$A$59,"Yes",Raw_Data!$D$2:$D$59,"จ่ายกลาง")/COUNTIFS(Raw_Data!$H$2:$H$59,">=1",Raw_Data!$H$2:$H$59,"<=5",Raw_Data!$A$2:$A$59,"Yes",Raw_Data!$D$2:$D$59,"จ่ายกลาง"),"") -> 100 | G5: =IFERROR(100*COUNTIFS(Raw_Data!$H$2:$H$59,">=4",Raw_Data!$H$2:$H$59,"<=5",Raw_Data!$A$2:$A$59,"Yes",Raw_Data!$D$2:$D$59,"ช่างและสนาม")/COUNTIFS(Raw_Data!$H$2:$H$59,">=1",Raw_Data!$H$2:$H$59,"<=5",Raw_Data!$A$2:$A$59,"Yes",Raw_Data!$D$2:$D$59,"ช่างและสนาม"),"") -> 75 | H5: =IFERROR(100*COUNTIFS(Raw_Data!$H$2:$H$59,">=4",Raw_Data!$H$2:$H$59,"<=5",Raw_Data!$A$2:$A$59,"Yes",Raw_Data!$D$2:$D$59,"ผู้ป่วยสัมพันธ์")/COUNTIFS(Raw_Data!$H$2:$H$59,">=1",Raw_Data!$H$2:$H$59,"<=5",Raw_Data!$A$2:$A$59,"Yes",Raw_Data!$D$2:$D$59,"ผู้ป่วยสัมพันธ์"),"") -> 50 | I5: =IFERROR(100*COUNTIFS(Raw_Data!$H$2:$H$59,">=4",Raw_Data!$H$2:$H$59,"<=5",Raw_Data!$A$2:$A$59,"Yes",Raw_Data!$D$2:$D$59,"ฝ่ายการพยาบาล")/COUNTIFS(Raw_Data!$H$2:$H$59,">=1",Raw_Data!$H$2:$H$59,"<=5",Raw_Data!$A$2:$A$59,"Yes",Raw_Data!$D$2:$D$59,"ฝ่ายการพยาบาล"),"") -> 50 | J5: =IFERROR(100*COUNTIFS(Raw_Data!$H$2:$H$59,">=4",Raw_Data!$H$2:$H$59,"<=5",Raw_Data!$A$2:$A$59,"Yes",Raw_Data!$D$2:$D$59,"โภชนาการ")/COUNTIFS(Raw_Data!$H$2:$H$59,">=1",Raw_Data!$H$2:$H$59,"<=5",Raw_Data!$A$2:$A$59,"Yes",Raw_Data!$D$2:$D$59,"โภชนาการ"),"") -> 100 | K5: =IFERROR(100*COUNTIFS(Raw_Data!$H$2:$H$59,">=4",Raw_Data!$H$2:$H$59,"<=5",Raw_Data!$A$2:$A$59,"Yes",Raw_Data!$D$2:$D$59,"ยานพาหนะ")/COUNTIFS(Raw_Data!$H$2:$H$59,">=1",Raw_Data!$H$2:$H$59,"<=5",Raw_Data!$A$2:$A$59,"Yes",Raw_Data!$D$2:$D$59,"ยานพาหนะ"),"") -> 0 | L5: =IFERROR(100*COUNTIFS(Raw_Data!$H$2:$H$59,">=4",Raw_Data!$H$2:$H$59,"<=5",Raw_Data!$A$2:$A$59,"Yes",Raw_Data!$D$2:$D$59,"สื่อสารการตลาด")/COUNTIFS(Raw_Data!$H$2:$H$59,">=1",Raw_Data!$H$2:$H$59,"<=5",Raw_Data!$A$2:$A$59,"Yes",Raw_Data!$D$2:$D$59,"สื่อสารการตลาด"),"") -> 100 | M5: =IFERROR(100*COUNTIFS(Raw_Data!$H$2:$H$59,">=4",Raw_Data!$H$2:$H$59,"<=5",Raw_Data!$A$2:$A$59,"Yes",Raw_Data!$D$2:$D$59,"ห้องยา")/COUNTIFS(Raw_Data!$H$2:$H$59,">=1",Raw_Data!$H$2:$H$59,"<=5",Raw_Data!$A$2:$A$59,"Yes",Raw_Data!$D$2:$D$59,"ห้องยา"),"") -> 100 | N5: =IFERROR(100*COUNTIFS(Raw_Data!$H$2:$H$59,">=4",Raw_Data!$H$2:$H$59,"<=5",Raw_Data!$A$2:$A$59,"Yes",Raw_Data!$D$2:$D$59,"ห้องแลป")/COUNTIFS(Raw_Data!$H$2:$H$59,">=1",Raw_Data!$H$2:$H$59,"<=5",Raw_Data!$A$2:$A$59,"Yes",Raw_Data!$D$2:$D$59,"ห้องแลป"),"") -> 0 | O5: =IFERROR(100*COUNTIFS(Raw_Data!$H$2:$H$59,">=4",Raw_Data!$H$2:$H$59,"<=5",Raw_Data!$A$2:$A$59,"Yes",Raw_Data!$D$2:$D$59,"ห้องเอ็กซเรย์")/COUNTIFS(Raw_Data!$H$2:$H$59,">=1",Raw_Data!$H$2:$H$59,"<=5",Raw_Data!$A$2:$A$59,"Yes",Raw_Data!$D$2:$D$59,"ห้องเอ็กซเรย์"),"") -> 100 | P5: =IFERROR(100*COUNTIFS(Raw_Data!$H$2:$H$59,">=4",Raw_Data!$H$2:$H$59,"<=5",Raw_Data!$A$2:$A$59,"Yes",Raw_Data!$D$2:$D$59,"ERและเปล")/COUNTIFS(Raw_Data!$H$2:$H$59,">=1",Raw_Data!$H$2:$H$59,"<=5",Raw_Data!$A$2:$A$59,"Yes",Raw_Data!$D$2:$D$59,"ERและเปล"),"") -> 36.363636 | Q5: =IFERROR(100*COUNTIFS(Raw_Data!$H$2:$H$59,">=4",Raw_Data!$H$2:$H$59,"<=5",Raw_Data!$A$2:$A$59,"Yes",Raw_Data!$D$2:$D$59,"HR")/COUNTIFS(Raw_Data!$H$2:$H$59,">=1",Raw_Data!$H$2:$H$59,"<=5",Raw_Data!$A$2:$A$59,"Yes",Raw_Data!$D$2:$D$59,"HR"),"") -> 100 | R5: =IFERROR(100*COUNTIFS(Raw_Data!$H$2:$H$59,">=4",Raw_Data!$H$2:$H$59,"<=5",Raw_Data!$A$2:$A$59,"Yes",Raw_Data!$D$2:$D$59,"ICU")/COUNTIFS(Raw_Data!$H$2:$H$59,">=1",Raw_Data!$H$2:$H$59,"<=5",Raw_Data!$A$2:$A$59,"Yes",Raw_Data!$D$2:$D$59,"ICU"),"") -> 100 | S5: =IFERROR(100*COUNTIFS(Raw_Data!$H$2:$H$59,">=4",Raw_Data!$H$2:$H$59,"<=5",Raw_Data!$A$2:$A$59,"Yes",Raw_Data!$D$2:$D$59,"IPD")/COUNTIFS(Raw_Data!$H$2:$H$59,">=1",Raw_Data!$H$2:$H$59,"<=5",Raw_Data!$A$2:$A$59,"Yes",Raw_Data!$D$2:$D$59,"IPD"),"") -> 66.666667 | T5: =IFERROR(100*COUNTIFS(Raw_Data!$H$2:$H$59,">=4",Raw_Data!$H$2:$H$59,"<=5",Raw_Data!$A$2:$A$59,"Yes",Raw_Data!$D$2:$D$59,"IT")/COUNTIFS(Raw_Data!$H$2:$H$59,">=1",Raw_Data!$H$2:$H$59,"<=5",Raw_Data!$A$2:$A$59,"Yes",Raw_Data!$D$2:$D$59,"IT"),"") -> 100 | U5: =IFERROR(100*COUNTIFS(Raw_Data!$H$2:$H$59,">=4",Raw_Data!$H$2:$H$59,"<=5",Raw_Data!$A$2:$A$59,"Yes",Raw_Data!$D$2:$D$59,"OR")/COUNTIFS(Raw_Data!$H$2:$H$59,">=1",Raw_Data!$H$2:$H$59,"<=5",Raw_Data!$A$2:$A$59,"Yes",Raw_Data!$D$2:$D$59,"OR"),"") -> 50 | V5: =IFERROR(100*COUNTIFS(Raw_Data!$H$2:$H$59,">=4",Raw_Data!$H$2:$H$59,"<=5",Raw_Data!$A$2:$A$59,"Yes",Raw_Data!$D$2:$D$59,"IPD",Raw_Data!$E$2:$E$59,"ผู้บริหาร")/COUNTIFS(Raw_Data!$H$2:$H$59,">=1",Raw_Data!$H$2:$H$59,"<=5",Raw_Data!$A$2:$A$59,"Yes",Raw_Data!$D$2:$D$59,"IPD",Raw_Data!$E$2:$E$59,"ผู้บริหาร"),"") -> 100 | W5: =IFERROR(100*COUNTIFS(Raw_Data!$H$2:$H$59,">=4",Raw_Data!$H$2:$H$59,"<=5",Raw_Data!$A$2:$A$59,"Yes",Raw_Data!$D$2:$D$59,"ฝ่ายการพยาบาล",Raw_Data!$E$2:$E$59,"สายวิชาชีพสาธารณสุข")/COUNTIFS(Raw_Data!$H$2:$H$59,">=1",Raw_Data!$H$2:$H$59,"<=5",Raw_Data!$A$2:$A$59,"Yes",Raw_Data!$D$2:$D$59,"ฝ่ายการพยาบาล",Raw_Data!$E$2:$E$59,"สายวิชาชีพสาธารณสุข"),"") -> 0 | X5: =IFERROR(100*COUNTIFS(Raw_Data!$H$2:$H$59,">=4",Raw_Data!$H$2:$H$59,"<=5",Raw_Data!$A$2:$A$59,"Yes",Raw_Data!$D$2:$D$59,"ERและเปล",Raw_Data!$E$2:$E$59,"สายวิชาชีพสาธารณสุข")/COUNTIFS(Raw_Data!$H$2:$H$59,">=1",Raw_Data!$H$2:$H$59,"<=5",Raw_Data!$A$2:$A$59,"Yes",Raw_Data!$D$2:$D$59,"ERและเปล",Raw_Data!$E$2:$E$59,"สายวิชาชีพสาธารณสุข"),"") -> 14.285714 | Y5: =IFERROR(100*COUNTIFS(Raw_Data!$H$2:$H$59,">=4",Raw_Data!$H$2:$H$59,"<=5",Raw_Data!$A$2:$A$59,"Yes",Raw_Data!$D$2:$D$59,"ICU",Raw_Data!$E$2:$E$59,"สายวิชาชีพสาธารณสุข")/COUNTIFS(Raw_Data!$H$2:$H$59,">=1",Raw_Data!$H$2:$H$59,"<=5",Raw_Data!$A$2:$A$59,"Yes",Raw_Data!$D$2:$D$59,"ICU",Raw_Data!$E$2:$E$59,"สายวิชาชีพสาธารณสุข"),"") -> 100 | Z5: =IFERROR(100*COUNTIFS(Raw_Data!$H$2:$H$59,">=4",Raw_Data!$H$2:$H$59,"<=5",Raw_Data!$A$2:$A$59,"Yes",Raw_Data!$D$2:$D$59,"IPD",Raw_Data!$E$2:$E$59,"สายวิชาชีพสาธารณสุข")/COUNTIFS(Raw_Data!$H$2:$H$59,">=1",Raw_Data!$H$2:$H$59,"<=5",Raw_Data!$A$2:$A$59,"Yes",Raw_Data!$D$2:$D$59,"IPD",Raw_Data!$E$2:$E$59,"สายวิชาชีพสาธารณสุข"),"") -> 100 | AA5: =IFERROR(100*COUNTIFS(Raw_Data!$H$2:$H$59,">=4",Raw_Data!$H$2:$H$59,"<=5",Raw_Data!$A$2:$A$59,"Yes",Raw_Data!$D$2:$D$59,"OR",Raw_Data!$E$2:$E$59,"สายวิชาชีพสาธารณสุข")/COUNTIFS(Raw_Data!$H$2:$H$59,">=1",Raw_Data!$H$2:$H$59,"<=5",Raw_Data!$A$2:$A$59,"Yes",Raw_Data!$D$2:$D$59,"OR",Raw_Data!$E$2:$E$59,"สายวิชาชีพสาธารณสุข"),"") -> 50 | AB5: =IFERROR(100*COUNTIFS(Raw_Data!$H$2:$H$59,">=4",Raw_Data!$H$2:$H$59,"<=5",Raw_Data!$A$2:$A$59,"Yes",Raw_Data!$D$2:$D$59,"การเงิน",Raw_Data!$E$2:$E$59,"สายสนับสนุนทั่วไป")/COUNTIFS(Raw_Data!$H$2:$H$59,">=1",Raw_Data!$H$2:$H$59,"<=5",Raw_Data!$A$2:$A$59,"Yes",Raw_Data!$D$2:$D$59,"การเงิน",Raw_Data!$E$2:$E$59,"สายสนับสนุนทั่วไป"),"") -> 33.333333 | AC5: =IFERROR(100*COUNTIFS(Raw_Data!$H$2:$H$59,">=4",Raw_Data!$H$2:$H$59,"<=5",Raw_Data!$A$2:$A$59,"Yes",Raw_Data!$D$2:$D$59,"เคหรักษ์",Raw_Data!$E$2:$E$59,"สายสนับสนุนทั่วไป")/COUNTIFS(Raw_Data!$H$2:$H$59,">=1",Raw_Data!$H$2:$H$59,"<=5",Raw_Data!$A$2:$A$59,"Yes",Raw_Data!$D$2:$D$59,"เคหรักษ์",Raw_Data!$E$2:$E$59,"สายสนับสนุนทั่วไป"),"") -> 0 | AD5: =IFERROR(100*COUNTIFS(Raw_Data!$H$2:$H$59,">=4",Raw_Data!$H$2:$H$59,"<=5",Raw_Data!$A$2:$A$59,"Yes",Raw_Data!$D$2:$D$59,"จ่ายกลาง",Raw_Data!$E$2:$E$59,"สายสนับสนุนทั่วไป")/COUNTIFS(Raw_Data!$H$2:$H$59,">=1",Raw_Data!$H$2:$H$59,"<=5",Raw_Data!$A$2:$A$59,"Yes",Raw_Data!$D$2:$D$59,"จ่ายกลาง",Raw_Data!$E$2:$E$59,"สายสนับสนุนทั่วไป"),"") -> 100 | AE5: =IFERROR(100*COUNTIFS(Raw_Data!$H$2:$H$59,">=4",Raw_Data!$H$2:$H$59,"<=5",Raw_Data!$A$2:$A$59,"Yes",Raw_Data!$D$2:$D$59,"ช่างและสนาม",Raw_Data!$E$2:$E$59,"สายสนับสนุนทั่วไป")/COUNTIFS(Raw_Data!$H$2:$H$59,">=1",Raw_Data!$H$2:$H$59,"<=5",Raw_Data!$A$2:$A$59,"Yes",Raw_Data!$D$2:$D$59,"ช่างและสนาม",Raw_Data!$E$2:$E$59,"สายสนับสนุนทั่วไป"),"") -> 75 | AF5: =IFERROR(100*COUNTIFS(Raw_Data!$H$2:$H$59,">=4",Raw_Data!$H$2:$H$59,"<=5",Raw_Data!$A$2:$A$59,"Yes",Raw_Data!$D$2:$D$59,"ผู้ป่วยสัมพันธ์",Raw_Data!$E$2:$E$59,"สายสนับสนุนทั่วไป")/COUNTIFS(Raw_Data!$H$2:$H$59,">=1",Raw_Data!$H$2:$H$59,"<=5",Raw_Data!$A$2:$A$59,"Yes",Raw_Data!$D$2:$D$59,"ผู้ป่วยสัมพันธ์",Raw_Data!$E$2:$E$59,"สายสนับสนุนทั่วไป"),"") -> 0 | AG5: =IFERROR(100*COUNTIFS(Raw_Data!$H$2:$H$59,">=4",Raw_Data!$H$2:$H$59,"<=5",Raw_Data!$A$2:$A$59,"Yes",Raw_Data!$D$2:$D$59,"ยานพาหนะ",Raw_Data!$E$2:$E$59,"สายสนับสนุนทั่วไป")/COUNTIFS(Raw_Data!$H$2:$H$59,">=1",Raw_Data!$H$2:$H$59,"<=5",Raw_Data!$A$2:$A$59,"Yes",Raw_Data!$D$2:$D$59,"ยานพาหนะ",Raw_Data!$E$2:$E$59,"สายสนับสนุนทั่วไป"),"") -> 0 | AH5: =IFERROR(100*COUNTIFS(Raw_Data!$H$2:$H$59,">=4",Raw_Data!$H$2:$H$59,"<=5",Raw_Data!$A$2:$A$59,"Yes",Raw_Data!$D$2:$D$59,"สื่อสารการตลาด",Raw_Data!$E$2:$E$59,"สายสนับสนุนทั่วไป")/COUNTIFS(Raw_Data!$H$2:$H$59,">=1",Raw_Data!$H$2:$H$59,"<=5",Raw_Data!$A$2:$A$59,"Yes",Raw_Data!$D$2:$D$59,"สื่อสารการตลาด",Raw_Data!$E$2:$E$59,"สายสนับสนุนทั่วไป"),"") -> 100 | AI5: =IFERROR(100*COUNTIFS(Raw_Data!$H$2:$H$59,">=4",Raw_Data!$H$2:$H$59,"<=5",Raw_Data!$A$2:$A$59,"Yes",Raw_Data!$D$2:$D$59,"ERและเปล",Raw_Data!$E$2:$E$59,"สายสนับสนุนทั่วไป")/COUNTIFS(Raw_Data!$H$2:$H$59,">=1",Raw_Data!$H$2:$H$59,"<=5",Raw_Data!$A$2:$A$59,"Yes",Raw_Data!$D$2:$D$59,"ERและเปล",Raw_Data!$E$2:$E$59,"สายสนับสนุนทั่วไป"),"") -> 100 | AJ5: =IFERROR(100*COUNTIFS(Raw_Data!$H$2:$H$59,">=4",Raw_Data!$H$2:$H$59,"<=5",Raw_Data!$A$2:$A$59,"Yes",Raw_Data!$D$2:$D$59,"HR",Raw_Data!$E$2:$E$59,"สายสนับสนุนทั่วไป")/COUNTIFS(Raw_Data!$H$2:$H$59,">=1",Raw_Data!$H$2:$H$59,"<=5",Raw_Data!$A$2:$A$59,"Yes",Raw_Data!$D$2:$D$59,"HR",Raw_Data!$E$2:$E$59,"สายสนับสนุนทั่วไป"),"") -> 100 | AK5: =IFERROR(100*COUNTIFS(Raw_Data!$H$2:$H$59,">=4",Raw_Data!$H$2:$H$59,"<=5",Raw_Data!$A$2:$A$59,"Yes",Raw_Data!$D$2:$D$59,"ICU",Raw_Data!$E$2:$E$59,"สายสนับสนุนทั่วไป")/COUNTIFS(Raw_Data!$H$2:$H$59,">=1",Raw_Data!$H$2:$H$59,"<=5",Raw_Data!$A$2:$A$59,"Yes",Raw_Data!$D$2:$D$59,"ICU",Raw_Data!$E$2:$E$59,"สายสนับสนุนทั่วไป"),"") -> 100 | AL5: =IFERROR(100*COUNTIFS(Raw_Data!$H$2:$H$59,">=4",Raw_Data!$H$2:$H$59,"<=5",Raw_Data!$A$2:$A$59,"Yes",Raw_Data!$D$2:$D$59,"IPD",Raw_Data!$E$2:$E$59,"สายสนับสนุนทั่วไป")/COUNTIFS(Raw_Data!$H$2:$H$59,">=1",Raw_Data!$H$2:$H$59,"<=5",Raw_Data!$A$2:$A$59,"Yes",Raw_Data!$D$2:$D$59,"IPD",Raw_Data!$E$2:$E$59,"สายสนับสนุนทั่วไป"),"") -> 0 | AM5: =IFERROR(100*COUNTIFS(Raw_Data!$H$2:$H$59,">=4",Raw_Data!$H$2:$H$59,"<=5",Raw_Data!$A$2:$A$59,"Yes",Raw_Data!$D$2:$D$59,"IT",Raw_Data!$E$2:$E$59,"สายสนับสนุนทั่วไป")/COUNTIFS(Raw_Data!$H$2:$H$59,">=1",Raw_Data!$H$2:$H$59,"<=5",Raw_Data!$A$2:$A$59,"Yes",Raw_Data!$D$2:$D$59,"IT",Raw_Data!$E$2:$E$59,"สายสนับสนุนทั่วไป"),"") -> 100 | AN5: =IFERROR(100*COUNTIFS(Raw_Data!$H$2:$H$59,">=4",Raw_Data!$H$2:$H$59,"<=5",Raw_Data!$A$2:$A$59,"Yes",Raw_Data!$D$2:$D$59,"ผู้ป่วยสัมพันธ์",Raw_Data!$E$2:$E$59,"สายสนับสนุนทางการแพทย์")/COUNTIFS(Raw_Data!$H$2:$H$59,">=1",Raw_Data!$H$2:$H$59,"<=5",Raw_Data!$A$2:$A$59,"Yes",Raw_Data!$D$2:$D$59,"ผู้ป่วยสัมพันธ์",Raw_Data!$E$2:$E$59,"สายสนับสนุนทางการแพทย์"),"") -> 66.666667 | AO5: =IFERROR(100*COUNTIFS(Raw_Data!$H$2:$H$59,">=4",Raw_Data!$H$2:$H$59,"<=5",Raw_Data!$A$2:$A$59,"Yes",Raw_Data!$D$2:$D$59,"ฝ่ายการพยาบาล",Raw_Data!$E$2:$E$59,"สายสนับสนุนทางการแพทย์")/COUNTIFS(Raw_Data!$H$2:$H$59,">=1",Raw_Data!$H$2:$H$59,"<=5",Raw_Data!$A$2:$A$59,"Yes",Raw_Data!$D$2:$D$59,"ฝ่ายการพยาบาล",Raw_Data!$E$2:$E$59,"สายสนับสนุนทางการแพทย์"),"") -> 100 | AP5: =IFERROR(100*COUNTIFS(Raw_Data!$H$2:$H$59,">=4",Raw_Data!$H$2:$H$59,"<=5",Raw_Data!$A$2:$A$59,"Yes",Raw_Data!$D$2:$D$59,"โภชนาการ",Raw_Data!$E$2:$E$59,"สายสนับสนุนทางการแพทย์")/COUNTIFS(Raw_Data!$H$2:$H$59,">=1",Raw_Data!$H$2:$H$59,"<=5",Raw_Data!$A$2:$A$59,"Yes",Raw_Data!$D$2:$D$59,"โภชนาการ",Raw_Data!$E$2:$E$59,"สายสนับสนุนทางการแพทย์"),"") -> 100 | AQ5: =IFERROR(100*COUNTIFS(Raw_Data!$H$2:$H$59,">=4",Raw_Data!$H$2:$H$59,"<=5",Raw_Data!$A$2:$A$59,"Yes",Raw_Data!$D$2:$D$59,"ห้องยา",Raw_Data!$E$2:$E$59,"สายสนับสนุนทางการแพทย์")/COUNTIFS(Raw_Data!$H$2:$H$59,">=1",Raw_Data!$H$2:$H$59,"<=5",Raw_Data!$A$2:$A$59,"Yes",Raw_Data!$D$2:$D$59,"ห้องยา",Raw_Data!$E$2:$E$59,"สายสนับสนุนทางการแพทย์"),"") -> 100 | AR5: =IFERROR(100*COUNTIFS(Raw_Data!$H$2:$H$59,">=4",Raw_Data!$H$2:$H$59,"<=5",Raw_Data!$A$2:$A$59,"Yes",Raw_Data!$D$2:$D$59,"ห้องแลป",Raw_Data!$E$2:$E$59,"สายสนับสนุนทางการแพทย์")/COUNTIFS(Raw_Data!$H$2:$H$59,">=1",Raw_Data!$H$2:$H$59,"<=5",Raw_Data!$A$2:$A$59,"Yes",Raw_Data!$D$2:$D$59,"ห้องแลป",Raw_Data!$E$2:$E$59,"สายสนับสนุนทางการแพทย์"),"") -> 0 | AS5: =IFERROR(100*COUNTIFS(Raw_Data!$H$2:$H$59,">=4",Raw_Data!$H$2:$H$59,"<=5",Raw_Data!$A$2:$A$59,"Yes",Raw_Data!$D$2:$D$59,"ห้องเอ็กซเรย์",Raw_Data!$E$2:$E$59,"สายสนับสนุนทางการแพทย์")/COUNTIFS(Raw_Data!$H$2:$H$59,">=1",Raw_Data!$H$2:$H$59,"<=5",Raw_Data!$A$2:$A$59,"Yes",Raw_Data!$D$2:$D$59,"ห้องเอ็กซเรย์",Raw_Data!$E$2:$E$59,"สายสนับสนุนทางการแพทย์"),"") -> 100 | AT5: =IFERROR(100*COUNTIFS(Raw_Data!$H$2:$H$59,">=4",Raw_Data!$H$2:$H$59,"<=5",Raw_Data!$A$2:$A$59,"Yes",Raw_Data!$D$2:$D$59,"ERและเปล",Raw_Data!$E$2:$E$59,"สายสนับสนุนทางการแพทย์")/COUNTIFS(Raw_Data!$H$2:$H$59,">=1",Raw_Data!$H$2:$H$59,"<=5",Raw_Data!$A$2:$A$59,"Yes",Raw_Data!$D$2:$D$59,"ERและเปล",Raw_Data!$E$2:$E$59,"สายสนับสนุนทางการแพทย์"),"") -> 0 | AU5: =IFERROR(100*COUNTIFS(Raw_Data!$H$2:$H$59,">=4",Raw_Data!$H$2:$H$59,"<=5",Raw_Data!$A$2:$A$59,"Yes",Raw_Data!$D$2:$D$59,"ICU",Raw_Data!$E$2:$E$59,"สายสนับสนุนทางการแพทย์")/COUNTIFS(Raw_Data!$H$2:$H$59,">=1",Raw_Data!$H$2:$H$59,"<=5",Raw_Data!$A$2:$A$59,"Yes",Raw_Data!$D$2:$D$59,"ICU",Raw_Data!$E$2:$E$59,"สายสนับสนุนทางการแพทย์"),"") -> 100 | AV5: =IFERROR(100*COUNTIFS(Raw_Data!$H$2:$H$59,">=4",Raw_Data!$H$2:$H$59,"<=5",Raw_Data!$A$2:$A$59,"Yes",Raw_Data!$D$2:$D$59,"IPD",Raw_Data!$E$2:$E$59,"สายสนับสนุนทางการแพทย์")/COUNTIFS(Raw_Data!$H$2:$H$59,">=1",Raw_Data!$H$2:$H$59,"<=5",Raw_Data!$A$2:$A$59,"Yes",Raw_Data!$D$2:$D$59,"IPD",Raw_Data!$E$2:$E$59,"สายสนับสนุนทางการแพทย์"),"") -> 50 | AW5: =IFERROR(100*COUNTIFS(Raw_Data!$H$2:$H$59,">=4",Raw_Data!$H$2:$H$59,"<=5",Raw_Data!$A$2:$A$59,"Yes",Raw_Data!$D$2:$D$59,"IT",Raw_Data!$E$2:$E$59,"สายสนับสนุนทางการแพทย์")/COUNTIFS(Raw_Data!$H$2:$H$59,">=1",Raw_Data!$H$2:$H$59,"<=5",Raw_Data!$A$2:$A$59,"Yes",Raw_Data!$D$2:$D$59,"IT",Raw_Data!$E$2:$E$59,"สายสนับสนุนทางการแพทย์"),"") -> 100
